Workbook

Sheet 2026-07-04
P1: RTSII | Q1: RTGII | R1: RTPDM2 | S1: RCC2 | T1: RTKL | U1: SCK2 | V1: SAB2 | W1: SAP2 | X1: SKJ2 | Y1: SSM2 | Z1: RKU2 | AA1: RJKU II | AB1: RMS II | AC1: ZSCCK | AD1: ZSCM | AE1: ZSCS | AF1: RJTS500 | AG1: RJMS500 | AH1: SCB | AI1: ZSCST | AJ1: SGK | AK1: DOT | AL1: ICK GT II | AM1: ICC II GT | AN1: ISC GT | AO1: IST GT | AP1: IBL GT | AQ1: ICO GT | AR1: IGC | AS1: SRC III | AT1: SCC III | AU1: SRM III | AV1: ZCRCC | AW1: ZCRCR | AX1: ZCRCB | AY1: SRS | AZ1: ZCRGC | BA1: DIC | BB1: DCP | BC1: DHF | BD1: DST | BE1: DPS | BF1: DNS | BG1: RKJ2 | BH1: RSM2 | BI1: RKS2 | BJ1: TOCII5S | BK1: TCCII5S | BL1: TCSII5S | BM1: TSTII5S | BN1: TCBII5S | BO1: KKM | BP1: RMNC | BQ1: RMNS | BR1: TDOC 72 | BS1: TDCC 72 | BT1: TDCS 72 | BU1: BURII | BV1: CCC | BW1: CCP | BX1: CCMS | BY1: STCB | BZ1: BMO | CA1: WFO | CB1: STCDC | CC1: MNC | CD1: BKOR
A2: No | B2: Tanggal | C2: Salesman Code | D2: Salesman Name | E2: Store | F2: Store Type | G2: Classification | H2: Sales Type | I2: Remarks | J2: Disc % | K2: CBP | L2: RBP | M2: RBP Net | N2: Qty | O2: # Items | P2: 15000 | Q2: 22000 | R2: 19000 | S2: 19500 | T2: 13500 | U2: 6000 | V2: 6000 | W2: 6000 | X2: 6000 | Y2: 6000 | Z2: 18000 | AA2: 21000 | AB2: 14500 | AC2: 5000 | AD2: 5000 | AE2: 5000 | AF2: 18000 | AG2: 18000 | AH2: 6000 | AI2: 5000 | AJ2: 6000 | AK2: 19500 | AL2: 4500 | AM2: 4500 | AN2: 4500 | AO2: 4500 | AP2: 4500 | AQ2: 4500 | AR2: 6000 | AS2: 5500 | AT2: 5500 | AU2: 5500 | AV2: 5500 | AW2: 5500 | AX2: 5500 | AY2: 5500 | AZ2: 6000 | BA2: 6500 | BB2: 6500 | BC2: 6000 | BD2: 6500 | BE2: 6500 | BF2: 6500 | BG2: 15000 | BH2: 11500 | BI2: 12000 | BJ2: 18000 | BK2: 18000 | BL2: 18000 | BM2: 19000 | BN2: 19000 | BO2: 12500 | BP2: 8000 | BQ2: 8000 | BR2: 9000 | BS2: 9000 | BT2: 9000 | BU2: 11000 | BV2: 5000 | BW2: 5000 | BX2: 5000 | BY2: 10000 | BZ2: 5000 | CA2: 5000 | CB2: 7000 | CC2: 6000 | CD2: 11000
A3: 1 | B3: 2026-07-04 | C3: 71306761 | D3: SMTR-01 | E3: (1881578329)AGIL TOKO | F3: WARUNG NOO | G3: WARUNG NOO | H3: Consignment | J3: 10 | K3: =(P2*P3)+(Q2*Q3)+(R2*R3)+(S2*S3)+(T2*T3)+(U2*U3)+(V2*V3)+(W2*W3)+(X2*X3)+(Y2*Y3)+(Z2*Z3)+(AA2*AA3)+(AB2*AB3)+(AC2*AC3)+(AD2*AD3)+(AE2*AE3)+(AF2*AF3)+(AG2*AG3)+(AH2*AH3)+(AI2*AI3)+(AJ2*AJ3)+(AK2*AK3)+(AL2*AL3)+(AM2*AM3)+(AN2*AN3)+(AO2*AO3)+(AP2*AP3)+(AQ2*AQ3)+(AR2*AR3)+(AS2*AS3)+(AT2*AT3)+(AU2*AU3)+(AV2*AV3)+(AW2*AW3)+(AX2*AX3)+(AY2*AY3)+(AZ2*AZ3)+(BA2*BA3)+(BB2*BB3)+(BC2*BC3)+(BD2*BD3)+(BE2*BE3)+(BF2*BF3)+(BG2*BG3)+(BH2*BH3)+(BI2*BI3)+(BJ2*BJ3)+(BK2*BK3)+(BL2*BL3)+(BM2*BM3)+(BN2*BN3)+(BO2*BO3)+(BP2*BP3)+(BQ2*BQ3)+(BR2*BR3)+(BS2*BS3)+(BT2*BT3)+(BU2*BU3)+(BV2*BV3)+(BW2*BW3)+(BX2*BX3)+(BY2*BY3)+(BZ2*BZ3)+(CA2*CA3)+(CB2*CB3)+(CC2*CC3)+(CD2*CD3) | L3: =K3-(K3*J3/100) | M3: =ROUND(L3/1.11, 2) | N3: =SUM(P3:CD3) | O3: =COUNTIF(P3:CD3,">0") | P3: 0 | Q3: 0 | R3: 0 | S3: 0 | T3: 0 | U3: 0 | V3: 0 | W3: 0 | X3: 0 | Y3: 0 | Z3: 0 | AA3: 0 | AB3: 0 | AC3: 0 | AD3: 0 | AE3: 0 | AF3: 0 | AG3: 0 | AH3: 0 | AI3: 0 | AJ3: 0 | AK3: 0 | AL3: 0 | AM3: 0 | AN3: 0 | AO3: 0 | AP3: 0 | AQ3: 0 | AR3: 0 | AS3: 0 | AT3: 0 | AU3: 0 | AV3: 0 | AW3: 0 | AX3: 0 | AY3: 0 | AZ3: 0 | BA3: 0 | BB3: 0 | BC3: 0 | BD3: 0 | BE3: 0 | BF3: 0 | BG3: 0 | BH3: 0 | BI3: 0 | BJ3: 0 | BK3: 0 | BL3: 0 | BM3: 0 | BN3: 0 | BO3: 0 | BP3: 0 | BQ3: 0 | BR3: 0 | BS3: 0 | BT3: 0 | BU3: 0 | BV3: 0 | BW3: 0 | BX3: 0 | BY3: 0 | BZ3: 0 | CA3: 0 | CB3: 0 | CC3: 0 | CD3: 0
A4: 2 | B4: 2026-07-04 | C4: 71306761 | D4: SMTR-01 | E4: (1881578393)AULIA TOKO | F4: WARUNG NOO | G4: WARUNG NOO | H4: Consignment | J4: 10 | K4: =(P2*P4)+(Q2*Q4)+(R2*R4)+(S2*S4)+(T2*T4)+(U2*U4)+(V2*V4)+(W2*W4)+(X2*X4)+(Y2*Y4)+(Z2*Z4)+(AA2*AA4)+(AB2*AB4)+(AC2*AC4)+(AD2*AD4)+(AE2*AE4)+(AF2*AF4)+(AG2*AG4)+(AH2*AH4)+(AI2*AI4)+(AJ2*AJ4)+(AK2*AK4)+(AL2*AL4)+(AM2*AM4)+(AN2*AN4)+(AO2*AO4)+(AP2*AP4)+(AQ2*AQ4)+(AR2*AR4)+(AS2*AS4)+(AT2*AT4)+(AU2*AU4)+(AV2*AV4)+(AW2*AW4)+(AX2*AX4)+(AY2*AY4)+(AZ2*AZ4)+(BA2*BA4)+(BB2*BB4)+(BC2*BC4)+(BD2*BD4)+(BE2*BE4)+(BF2*BF4)+(BG2*BG4)+(BH2*BH4)+(BI2*BI4)+(BJ2*BJ4)+(BK2*BK4)+(BL2*BL4)+(BM2*BM4)+(BN2*BN4)+(BO2*BO4)+(BP2*BP4)+(BQ2*BQ4)+(BR2*BR4)+(BS2*BS4)+(BT2*BT4)+(BU2*BU4)+(BV2*BV4)+(BW2*BW4)+(BX2*BX4)+(BY2*BY4)+(BZ2*BZ4)+(CA2*CA4)+(CB2*CB4)+(CC2*CC4)+(CD2*CD4) | L4: =K4-(K4*J4/100) | M4: =ROUND(L4/1.11, 2) | N4: =SUM(P4:CD4) | O4: =COUNTIF(P4:CD4,">0") | P4: 0 | Q4: 0 | R4: 0 | S4: 0 | T4: 0 | U4: 0 | V4: 0 | W4: 0 | X4: 0 | Y4: 0 | Z4: 0 | AA4: 0 | AB4: 0 | AC4: 0 | AD4: 0 | AE4: 0 | AF4: 0 | AG4: 0 | AH4: 0 | AI4: 0 | AJ4: 0 | AK4: 0 | AL4: 0 | AM4: 0 | AN4: 0 | AO4: 0 | AP4: 0 | AQ4: 0 | AR4: 0 | AS4: 0 | AT4: 0 | AU4: 0 | AV4: 0 | AW4: 0 | AX4: 0 | AY4: 0 | AZ4: 0 | BA4: 0 | BB4: 0 | BC4: 0 | BD4: 0 | BE4: 0 | BF4: 0 | BG4: 0 | BH4: 0 | BI4: 0 | BJ4: 0 | BK4: 0 | BL4: 0 | BM4: 0 | BN4: 0 | BO4: 0 | BP4: 0 | BQ4: 0 | BR4: 0 | BS4: 0 | BT4: 0 | BU4: 0 | BV4: 0 | BW4: 0 | BX4: 0 | BY4: 0 | BZ4: 0 | CA4: 0 | CB4: 0 | CC4: 0 | CD4: 0
A5: 3 | B5: 2026-07-04 | C5: 71306761 | D5: SMTR-01 | E5: (1881578394)SRI WAHYUNI TOKO | F5: WARUNG NOO | G5: WARUNG NOO | H5: Consignment | J5: 10 | K5: =(P2*P5)+(Q2*Q5)+(R2*R5)+(S2*S5)+(T2*T5)+(U2*U5)+(V2*V5)+(W2*W5)+(X2*X5)+(Y2*Y5)+(Z2*Z5)+(AA2*AA5)+(AB2*AB5)+(AC2*AC5)+(AD2*AD5)+(AE2*AE5)+(AF2*AF5)+(AG2*AG5)+(AH2*AH5)+(AI2*AI5)+(AJ2*AJ5)+(AK2*AK5)+(AL2*AL5)+(AM2*AM5)+(AN2*AN5)+(AO2*AO5)+(AP2*AP5)+(AQ2*AQ5)+(AR2*AR5)+(AS2*AS5)+(AT2*AT5)+(AU2*AU5)+(AV2*AV5)+(AW2*AW5)+(AX2*AX5)+(AY2*AY5)+(AZ2*AZ5)+(BA2*BA5)+(BB2*BB5)+(BC2*BC5)+(BD2*BD5)+(BE2*BE5)+(BF2*BF5)+(BG2*BG5)+(BH2*BH5)+(BI2*BI5)+(BJ2*BJ5)+(BK2*BK5)+(BL2*BL5)+(BM2*BM5)+(BN2*BN5)+(BO2*BO5)+(BP2*BP5)+(BQ2*BQ5)+(BR2*BR5)+(BS2*BS5)+(BT2*BT5)+(BU2*BU5)+(BV2*BV5)+(BW2*BW5)+(BX2*BX5)+(BY2*BY5)+(BZ2*BZ5)+(CA2*CA5)+(CB2*CB5)+(CC2*CC5)+(CD2*CD5) | L5: =K5-(K5*J5/100) | M5: =ROUND(L5/1.11, 2) | N5: =SUM(P5:CD5) | O5: =COUNTIF(P5:CD5,">0") | P5: 0 | Q5: 0 | R5: 0 | S5: 0 | T5: 0 | U5: 0 | V5: 0 | W5: 0 | X5: 0 | Y5: 0 | Z5: 0 | AA5: 0 | AB5: 0 | AC5: 0 | AD5: 0 | AE5: 0 | AF5: 0 | AG5: 0 | AH5: 0 | AI5: 0 | AJ5: 0 | AK5: 0 | AL5: 0 | AM5: 0 | AN5: 0 | AO5: 0 | AP5: 0 | AQ5: 0 | AR5: 0 | AS5: 0 | AT5: 0 | AU5: 0 | AV5: 0 | AW5: 0 | AX5: 0 | AY5: 0 | AZ5: 0 | BA5: 0 | BB5: 0 | BC5: 0 | BD5: 0 | BE5: 0 | BF5: 0 | BG5: 0 | BH5: 0 | BI5: 0 | BJ5: 0 | BK5: 0 | BL5: 0 | BM5: 0 | BN5: 0 | BO5: 0 | BP5: 0 | BQ5: 0 | BR5: 0 | BS5: 0 | BT5: 0 | BU5: 0 | BV5: 0 | BW5: 0 | BX5: 0 | BY5: 0 | BZ5: 0 | CA5: 0 | CB5: 0 | CC5: 0 | CD5: 0
A6: 4 | B6: 2026-07-04 | C6: 71306761 | D6: SMTR-01 | E6: (1881578396)S MART | F6: MTI NOO | G6: MTI NOO | H6: Consignment | J6: 10 | K6: =(P2*P6)+(Q2*Q6)+(R2*R6)+(S2*S6)+(T2*T6)+(U2*U6)+(V2*V6)+(W2*W6)+(X2*X6)+(Y2*Y6)+(Z2*Z6)+(AA2*AA6)+(AB2*AB6)+(AC2*AC6)+(AD2*AD6)+(AE2*AE6)+(AF2*AF6)+(AG2*AG6)+(AH2*AH6)+(AI2*AI6)+(AJ2*AJ6)+(AK2*AK6)+(AL2*AL6)+(AM2*AM6)+(AN2*AN6)+(AO2*AO6)+(AP2*AP6)+(AQ2*AQ6)+(AR2*AR6)+(AS2*AS6)+(AT2*AT6)+(AU2*AU6)+(AV2*AV6)+(AW2*AW6)+(AX2*AX6)+(AY2*AY6)+(AZ2*AZ6)+(BA2*BA6)+(BB2*BB6)+(BC2*BC6)+(BD2*BD6)+(BE2*BE6)+(BF2*BF6)+(BG2*BG6)+(BH2*BH6)+(BI2*BI6)+(BJ2*BJ6)+(BK2*BK6)+(BL2*BL6)+(BM2*BM6)+(BN2*BN6)+(BO2*BO6)+(BP2*BP6)+(BQ2*BQ6)+(BR2*BR6)+(BS2*BS6)+(BT2*BT6)+(BU2*BU6)+(BV2*BV6)+(BW2*BW6)+(BX2*BX6)+(BY2*BY6)+(BZ2*BZ6)+(CA2*CA6)+(CB2*CB6)+(CC2*CC6)+(CD2*CD6) | L6: =K6-(K6*J6/100) | M6: =ROUND(L6/1.11, 2) | N6: =SUM(P6:CD6) | O6: =COUNTIF(P6:CD6,">0") | P6: 0 | Q6: 0 | R6: 0 | S6: 0 | T6: 0 | U6: 0 | V6: 0 | W6: 0 | X6: 0 | Y6: 0 | Z6: 0 | AA6: 0 | AB6: 0 | AC6: 0 | AD6: 0 | AE6: 0 | AF6: 0 | AG6: 0 | AH6: 0 | AI6: 0 | AJ6: 0 | AK6: 0 | AL6: 0 | AM6: 0 | AN6: 0 | AO6: 0 | AP6: 0 | AQ6: 0 | AR6: 0 | AS6: 0 | AT6: 0 | AU6: 0 | AV6: 0 | AW6: 0 | AX6: 0 | AY6: 0 | AZ6: 0 | BA6: 0 | BB6: 0 | BC6: 0 | BD6: 0 | BE6: 0 | BF6: 0 | BG6: 0 | BH6: 0 | BI6: 0 | BJ6: 0 | BK6: 0 | BL6: 0 | BM6: 0 | BN6: 0 | BO6: 0 | BP6: 0 | BQ6: 0 | BR6: 0 | BS6: 0 | BT6: 0 | BU6: 0 | BV6: 0 | BW6: 0 | BX6: 0 | BY6: 0 | BZ6: 0 | CA6: 0 | CB6: 0 | CC6: 0 | CD6: 0
A7: 5 | B7: 2026-07-04 | C7: 71306761 | D7: SMTR-01 | E7: (1881578398)UCOK ALI TOKO | F7: WARUNG NOO | G7: WARUNG NOO | H7: Consignment | J7: 10 | K7: =(P2*P7)+(Q2*Q7)+(R2*R7)+(S2*S7)+(T2*T7)+(U2*U7)+(V2*V7)+(W2*W7)+(X2*X7)+(Y2*Y7)+(Z2*Z7)+(AA2*AA7)+(AB2*AB7)+(AC2*AC7)+(AD2*AD7)+(AE2*AE7)+(AF2*AF7)+(AG2*AG7)+(AH2*AH7)+(AI2*AI7)+(AJ2*AJ7)+(AK2*AK7)+(AL2*AL7)+(AM2*AM7)+(AN2*AN7)+(AO2*AO7)+(AP2*AP7)+(AQ2*AQ7)+(AR2*AR7)+(AS2*AS7)+(AT2*AT7)+(AU2*AU7)+(AV2*AV7)+(AW2*AW7)+(AX2*AX7)+(AY2*AY7)+(AZ2*AZ7)+(BA2*BA7)+(BB2*BB7)+(BC2*BC7)+(BD2*BD7)+(BE2*BE7)+(BF2*BF7)+(BG2*BG7)+(BH2*BH7)+(BI2*BI7)+(BJ2*BJ7)+(BK2*BK7)+(BL2*BL7)+(BM2*BM7)+(BN2*BN7)+(BO2*BO7)+(BP2*BP7)+(BQ2*BQ7)+(BR2*BR7)+(BS2*BS7)+(BT2*BT7)+(BU2*BU7)+(BV2*BV7)+(BW2*BW7)+(BX2*BX7)+(BY2*BY7)+(BZ2*BZ7)+(CA2*CA7)+(CB2*CB7)+(CC2*CC7)+(CD2*CD7) | L7: =K7-(K7*J7/100) | M7: =ROUND(L7/1.11, 2) | N7: =SUM(P7:CD7) | O7: =COUNTIF(P7:CD7,">0") | P7: 0 | Q7: 0 | R7: 0 | S7: 0 | T7: 0 | U7: 0 | V7: 0 | W7: 0 | X7: 0 | Y7: 0 | Z7: 0 | AA7: 0 | AB7: 0 | AC7: 0 | AD7: 0 | AE7: 0 | AF7: 0 | AG7: 0 | AH7: 0 | AI7: 0 | AJ7: 0 | AK7: 0 | AL7: 0 | AM7: 0 | AN7: 0 | AO7: 0 | AP7: 0 | AQ7: 0 | AR7: 0 | AS7: 0 | AT7: 0 | AU7: 0 | AV7: 0 | AW7: 0 | AX7: 0 | AY7: 0 | AZ7: 0 | BA7: 0 | BB7: 0 | BC7: 0 | BD7: 0 | BE7: 0 | BF7: 0 | BG7: 0 | BH7: 0 | BI7: 0 | BJ7: 0 | BK7: 0 | BL7: 0 | BM7: 0 | BN7: 0 | BO7: 0 | BP7: 0 | BQ7: 0 | BR7: 0 | BS7: 0 | BT7: 0 | BU7: 0 | BV7: 0 | BW7: 0 | BX7: 0 | BY7: 0 | BZ7: 0 | CA7: 0 | CB7: 0 | CC7: 0 | CD7: 0
A8: 6 | B8: 2026-07-04 | C8: 71306761 | D8: SMTR-01 | E8: (1881578399)ARHAM TOKO | F8: WARUNG NOO | G8: WARUNG NOO | H8: Consignment | J8: 10 | K8: =(P2*P8)+(Q2*Q8)+(R2*R8)+(S2*S8)+(T2*T8)+(U2*U8)+(V2*V8)+(W2*W8)+(X2*X8)+(Y2*Y8)+(Z2*Z8)+(AA2*AA8)+(AB2*AB8)+(AC2*AC8)+(AD2*AD8)+(AE2*AE8)+(AF2*AF8)+(AG2*AG8)+(AH2*AH8)+(AI2*AI8)+(AJ2*AJ8)+(AK2*AK8)+(AL2*AL8)+(AM2*AM8)+(AN2*AN8)+(AO2*AO8)+(AP2*AP8)+(AQ2*AQ8)+(AR2*AR8)+(AS2*AS8)+(AT2*AT8)+(AU2*AU8)+(AV2*AV8)+(AW2*AW8)+(AX2*AX8)+(AY2*AY8)+(AZ2*AZ8)+(BA2*BA8)+(BB2*BB8)+(BC2*BC8)+(BD2*BD8)+(BE2*BE8)+(BF2*BF8)+(BG2*BG8)+(BH2*BH8)+(BI2*BI8)+(BJ2*BJ8)+(BK2*BK8)+(BL2*BL8)+(BM2*BM8)+(BN2*BN8)+(BO2*BO8)+(BP2*BP8)+(BQ2*BQ8)+(BR2*BR8)+(BS2*BS8)+(BT2*BT8)+(BU2*BU8)+(BV2*BV8)+(BW2*BW8)+(BX2*BX8)+(BY2*BY8)+(BZ2*BZ8)+(CA2*CA8)+(CB2*CB8)+(CC2*CC8)+(CD2*CD8) | L8: =K8-(K8*J8/100) | M8: =ROUND(L8/1.11, 2) | N8: =SUM(P8:CD8) | O8: =COUNTIF(P8:CD8,">0") | P8: 0 | Q8: 0 | R8: 0 | S8: 0 | T8: 0 | U8: 0 | V8: 0 | W8: 0 | X8: 0 | Y8: 0 | Z8: 0 | AA8: 0 | AB8: 0 | AC8: 0 | AD8: 0 | AE8: 0 | AF8: 0 | AG8: 0 | AH8: 0 | AI8: 0 | AJ8: 0 | AK8: 0 | AL8: 0 | AM8: 0 | AN8: 0 | AO8: 0 | AP8: 0 | AQ8: 0 | AR8: 0 | AS8: 0 | AT8: 0 | AU8: 0 | AV8: 0 | AW8: 0 | AX8: 0 | AY8: 0 | AZ8: 0 | BA8: 0 | BB8: 0 | BC8: 0 | BD8: 0 | BE8: 0 | BF8: 0 | BG8: 0 | BH8: 0 | BI8: 0 | BJ8: 0 | BK8: 0 | BL8: 0 | BM8: 0 | BN8: 0 | BO8: 0 | BP8: 0 | BQ8: 0 | BR8: 0 | BS8: 0 | BT8: 0 | BU8: 0 | BV8: 0 | BW8: 0 | BX8: 0 | BY8: 0 | BZ8: 0 | CA8: 0 | CB8: 0 | CC8: 0 | CD8: 0
A9: 7 | B9: 2026-07-04 | C9: 71306761 | D9: SMTR-01 | E9: (1881578401)KLINIK NURDIN WAHID KANTIN | F9: RUMAH SAKIT | G9: LAYANAN KESEHATAN | H9: Consignment | J9: 10 | K9: =(P2*P9)+(Q2*Q9)+(R2*R9)+(S2*S9)+(T2*T9)+(U2*U9)+(V2*V9)+(W2*W9)+(X2*X9)+(Y2*Y9)+(Z2*Z9)+(AA2*AA9)+(AB2*AB9)+(AC2*AC9)+(AD2*AD9)+(AE2*AE9)+(AF2*AF9)+(AG2*AG9)+(AH2*AH9)+(AI2*AI9)+(AJ2*AJ9)+(AK2*AK9)+(AL2*AL9)+(AM2*AM9)+(AN2*AN9)+(AO2*AO9)+(AP2*AP9)+(AQ2*AQ9)+(AR2*AR9)+(AS2*AS9)+(AT2*AT9)+(AU2*AU9)+(AV2*AV9)+(AW2*AW9)+(AX2*AX9)+(AY2*AY9)+(AZ2*AZ9)+(BA2*BA9)+(BB2*BB9)+(BC2*BC9)+(BD2*BD9)+(BE2*BE9)+(BF2*BF9)+(BG2*BG9)+(BH2*BH9)+(BI2*BI9)+(BJ2*BJ9)+(BK2*BK9)+(BL2*BL9)+(BM2*BM9)+(BN2*BN9)+(BO2*BO9)+(BP2*BP9)+(BQ2*BQ9)+(BR2*BR9)+(BS2*BS9)+(BT2*BT9)+(BU2*BU9)+(BV2*BV9)+(BW2*BW9)+(BX2*BX9)+(BY2*BY9)+(BZ2*BZ9)+(CA2*CA9)+(CB2*CB9)+(CC2*CC9)+(CD2*CD9) | L9: =K9-(K9*J9/100) | M9: =ROUND(L9/1.11, 2) | N9: =SUM(P9:CD9) | O9: =COUNTIF(P9:CD9,">0") | P9: 0 | Q9: 0 | R9: 0 | S9: 0 | T9: 0 | U9: 0 | V9: 0 | W9: 0 | X9: 0 | Y9: 0 | Z9: 0 | AA9: 0 | AB9: 0 | AC9: 0 | AD9: 0 | AE9: 0 | AF9: 0 | AG9: 0 | AH9: 0 | AI9: 0 | AJ9: 0 | AK9: 0 | AL9: 0 | AM9: 0 | AN9: 0 | AO9: 0 | AP9: 0 | AQ9: 0 | AR9: 0 | AS9: 0 | AT9: 0 | AU9: 0 | AV9: 0 | AW9: 0 | AX9: 0 | AY9: 0 | AZ9: 0 | BA9: 0 | BB9: 0 | BC9: 0 | BD9: 0 | BE9: 0 | BF9: 0 | BG9: 0 | BH9: 0 | BI9: 0 | BJ9: 0 | BK9: 0 | BL9: 0 | BM9: 0 | BN9: 0 | BO9: 0 | BP9: 0 | BQ9: 0 | BR9: 0 | BS9: 0 | BT9: 0 | BU9: 0 | BV9: 0 | BW9: 0 | BX9: 0 | BY9: 0 | BZ9: 0 | CA9: 0 | CB9: 0 | CC9: 0 | CD9: 0
A10: 8 | B10: 2026-07-04 | C10: 71306761 | D10: SMTR-01 | E10: (1881578402)RAHMAN TOKO | F10: WARUNG NOO | G10: WARUNG NOO | H10: Consignment | J10: 10 | K10: =(P2*P10)+(Q2*Q10)+(R2*R10)+(S2*S10)+(T2*T10)+(U2*U10)+(V2*V10)+(W2*W10)+(X2*X10)+(Y2*Y10)+(Z2*Z10)+(AA2*AA10)+(AB2*AB10)+(AC2*AC10)+(AD2*AD10)+(AE2*AE10)+(AF2*AF10)+(AG2*AG10)+(AH2*AH10)+(AI2*AI10)+(AJ2*AJ10)+(AK2*AK10)+(AL2*AL10)+(AM2*AM10)+(AN2*AN10)+(AO2*AO10)+(AP2*AP10)+(AQ2*AQ10)+(AR2*AR10)+(AS2*AS10)+(AT2*AT10)+(AU2*AU10)+(AV2*AV10)+(AW2*AW10)+(AX2*AX10)+(AY2*AY10)+(AZ2*AZ10)+(BA2*BA10)+(BB2*BB10)+(BC2*BC10)+(BD2*BD10)+(BE2*BE10)+(BF2*BF10)+(BG2*BG10)+(BH2*BH10)+(BI2*BI10)+(BJ2*BJ10)+(BK2*BK10)+(BL2*BL10)+(BM2*BM10)+(BN2*BN10)+(BO2*BO10)+(BP2*BP10)+(BQ2*BQ10)+(BR2*BR10)+(BS2*BS10)+(BT2*BT10)+(BU2*BU10)+(BV2*BV10)+(BW2*BW10)+(BX2*BX10)+(BY2*BY10)+(BZ2*BZ10)+(CA2*CA10)+(CB2*CB10)+(CC2*CC10)+(CD2*CD10) | L10: =K10-(K10*J10/100) | M10: =ROUND(L10/1.11, 2) | N10: =SUM(P10:CD10) | O10: =COUNTIF(P10:CD10,">0") | P10: 0 | Q10: 0 | R10: 0 | S10: 0 | T10: 0 | U10: 0 | V10: 0 | W10: 0 | X10: 0 | Y10: 0 | Z10: 0 | AA10: 0 | AB10: 0 | AC10: 0 | AD10: 0 | AE10: 0 | AF10: 0 | AG10: 0 | AH10: 0 | AI10: 0 | AJ10: 0 | AK10: 0 | AL10: 0 | AM10: 0 | AN10: 0 | AO10: 0 | AP10: 0 | AQ10: 0 | AR10: 0 | AS10: 0 | AT10: 0 | AU10: 0 | AV10: 0 | AW10: 0 | AX10: 0 | AY10: 0 | AZ10: 0 | BA10: 0 | BB10: 0 | BC10: 0 | BD10: 0 | BE10: 0 | BF10: 0 | BG10: 0 | BH10: 0 | BI10: 0 | BJ10: 0 | BK10: 0 | BL10: 0 | BM10: 0 | BN10: 0 | BO10: 0 | BP10: 0 | BQ10: 0 | BR10: 0 | BS10: 0 | BT10: 0 | BU10: 0 | BV10: 0 | BW10: 0 | BX10: 0 | BY10: 0 | BZ10: 0 | CA10: 0 | CB10: 0 | CC10: 0 | CD10: 0
A11: 9 | B11: 2026-07-04 | C11: 71306761 | D11: SMTR-01 | E11: (1881578403)RESTU CELL | F11: WARUNG NOO | G11: WARUNG NOO | H11: Consignment | J11: 10 | K11: =(P2*P11)+(Q2*Q11)+(R2*R11)+(S2*S11)+(T2*T11)+(U2*U11)+(V2*V11)+(W2*W11)+(X2*X11)+(Y2*Y11)+(Z2*Z11)+(AA2*AA11)+(AB2*AB11)+(AC2*AC11)+(AD2*AD11)+(AE2*AE11)+(AF2*AF11)+(AG2*AG11)+(AH2*AH11)+(AI2*AI11)+(AJ2*AJ11)+(AK2*AK11)+(AL2*AL11)+(AM2*AM11)+(AN2*AN11)+(AO2*AO11)+(AP2*AP11)+(AQ2*AQ11)+(AR2*AR11)+(AS2*AS11)+(AT2*AT11)+(AU2*AU11)+(AV2*AV11)+(AW2*AW11)+(AX2*AX11)+(AY2*AY11)+(AZ2*AZ11)+(BA2*BA11)+(BB2*BB11)+(BC2*BC11)+(BD2*BD11)+(BE2*BE11)+(BF2*BF11)+(BG2*BG11)+(BH2*BH11)+(BI2*BI11)+(BJ2*BJ11)+(BK2*BK11)+(BL2*BL11)+(BM2*BM11)+(BN2*BN11)+(BO2*BO11)+(BP2*BP11)+(BQ2*BQ11)+(BR2*BR11)+(BS2*BS11)+(BT2*BT11)+(BU2*BU11)+(BV2*BV11)+(BW2*BW11)+(BX2*BX11)+(BY2*BY11)+(BZ2*BZ11)+(CA2*CA11)+(CB2*CB11)+(CC2*CC11)+(CD2*CD11) | L11: =K11-(K11*J11/100) | M11: =ROUND(L11/1.11, 2) | N11: =SUM(P11:CD11) | O11: =COUNTIF(P11:CD11,">0") | P11: 0 | Q11: 0 | R11: 0 | S11: 0 | T11: 0 | U11: 0 | V11: 0 | W11: 0 | X11: 0 | Y11: 0 | Z11: 0 | AA11: 0 | AB11: 0 | AC11: 0 | AD11: 0 | AE11: 0 | AF11: 0 | AG11: 0 | AH11: 0 | AI11: 0 | AJ11: 0 | AK11: 0 | AL11: 0 | AM11: 0 | AN11: 0 | AO11: 0 | AP11: 0 | AQ11: 0 | AR11: 0 | AS11: 0 | AT11: 0 | AU11: 0 | AV11: 0 | AW11: 0 | AX11: 0 | AY11: 0 | AZ11: 0 | BA11: 0 | BB11: 0 | BC11: 0 | BD11: 0 | BE11: 0 | BF11: 0 | BG11: 0 | BH11: 0 | BI11: 0 | BJ11: 0 | BK11: 0 | BL11: 0 | BM11: 0 | BN11: 0 | BO11: 0 | BP11: 0 | BQ11: 0 | BR11: 0 | BS11: 0 | BT11: 0 | BU11: 0 | BV11: 0 | BW11: 0 | BX11: 0 | BY11: 0 | BZ11: 0 | CA11: 0 | CB11: 0 | CC11: 0 | CD11: 0
A12: 10 | B12: 2026-07-04 | C12: 71306761 | D12: SMTR-01 | E12: (1881578407)AZIFA RANGKUTI TOKO | F12: WARUNG NOO | G12: WARUNG NOO | H12: Consignment | J12: 10 | K12: =(P2*P12)+(Q2*Q12)+(R2*R12)+(S2*S12)+(T2*T12)+(U2*U12)+(V2*V12)+(W2*W12)+(X2*X12)+(Y2*Y12)+(Z2*Z12)+(AA2*AA12)+(AB2*AB12)+(AC2*AC12)+(AD2*AD12)+(AE2*AE12)+(AF2*AF12)+(AG2*AG12)+(AH2*AH12)+(AI2*AI12)+(AJ2*AJ12)+(AK2*AK12)+(AL2*AL12)+(AM2*AM12)+(AN2*AN12)+(AO2*AO12)+(AP2*AP12)+(AQ2*AQ12)+(AR2*AR12)+(AS2*AS12)+(AT2*AT12)+(AU2*AU12)+(AV2*AV12)+(AW2*AW12)+(AX2*AX12)+(AY2*AY12)+(AZ2*AZ12)+(BA2*BA12)+(BB2*BB12)+(BC2*BC12)+(BD2*BD12)+(BE2*BE12)+(BF2*BF12)+(BG2*BG12)+(BH2*BH12)+(BI2*BI12)+(BJ2*BJ12)+(BK2*BK12)+(BL2*BL12)+(BM2*BM12)+(BN2*BN12)+(BO2*BO12)+(BP2*BP12)+(BQ2*BQ12)+(BR2*BR12)+(BS2*BS12)+(BT2*BT12)+(BU2*BU12)+(BV2*BV12)+(BW2*BW12)+(BX2*BX12)+(BY2*BY12)+(BZ2*BZ12)+(CA2*CA12)+(CB2*CB12)+(CC2*CC12)+(CD2*CD12) | L12: =K12-(K12*J12/100) | M12: =ROUND(L12/1.11, 2) | N12: =SUM(P12:CD12) | O12: =COUNTIF(P12:CD12,">0") | P12: 0 | Q12: 0 | R12: 0 | S12: 0 | T12: 0 | U12: 0 | V12: 0 | W12: 0 | X12: 0 | Y12: 0 | Z12: 0 | AA12: 0 | AB12: 0 | AC12: 0 | AD12: 0 | AE12: 0 | AF12: 0 | AG12: 0 | AH12: 0 | AI12: 0 | AJ12: 0 | AK12: 0 | AL12: 0 | AM12: 0 | AN12: 0 | AO12: 0 | AP12: 0 | AQ12: 0 | AR12: 0 | AS12: 0 | AT12: 0 | AU12: 0 | AV12: 0 | AW12: 0 | AX12: 0 | AY12: 0 | AZ12: 0 | BA12: 0 | BB12: 0 | BC12: 0 | BD12: 0 | BE12: 0 | BF12: 0 | BG12: 0 | BH12: 0 | BI12: 0 | BJ12: 0 | BK12: 0 | BL12: 0 | BM12: 0 | BN12: 0 | BO12: 0 | BP12: 0 | BQ12: 0 | BR12: 0 | BS12: 0 | BT12: 0 | BU12: 0 | BV12: 0 | BW12: 0 | BX12: 0 | BY12: 0 | BZ12: 0 | CA12: 0 | CB12: 0 | CC12: 0 | CD12: 0
A13: 11 | B13: 2026-07-04 | C13: 71306761 | D13: SMTR-01 | E13: (1881578489)KLINIK ANANDA KANTIN | F13: RUMAH SAKIT | G13: LAYANAN KESEHATAN | H13: Consignment | J13: 10 | K13: =(P2*P13)+(Q2*Q13)+(R2*R13)+(S2*S13)+(T2*T13)+(U2*U13)+(V2*V13)+(W2*W13)+(X2*X13)+(Y2*Y13)+(Z2*Z13)+(AA2*AA13)+(AB2*AB13)+(AC2*AC13)+(AD2*AD13)+(AE2*AE13)+(AF2*AF13)+(AG2*AG13)+(AH2*AH13)+(AI2*AI13)+(AJ2*AJ13)+(AK2*AK13)+(AL2*AL13)+(AM2*AM13)+(AN2*AN13)+(AO2*AO13)+(AP2*AP13)+(AQ2*AQ13)+(AR2*AR13)+(AS2*AS13)+(AT2*AT13)+(AU2*AU13)+(AV2*AV13)+(AW2*AW13)+(AX2*AX13)+(AY2*AY13)+(AZ2*AZ13)+(BA2*BA13)+(BB2*BB13)+(BC2*BC13)+(BD2*BD13)+(BE2*BE13)+(BF2*BF13)+(BG2*BG13)+(BH2*BH13)+(BI2*BI13)+(BJ2*BJ13)+(BK2*BK13)+(BL2*BL13)+(BM2*BM13)+(BN2*BN13)+(BO2*BO13)+(BP2*BP13)+(BQ2*BQ13)+(BR2*BR13)+(BS2*BS13)+(BT2*BT13)+(BU2*BU13)+(BV2*BV13)+(BW2*BW13)+(BX2*BX13)+(BY2*BY13)+(BZ2*BZ13)+(CA2*CA13)+(CB2*CB13)+(CC2*CC13)+(CD2*CD13) | L13: =K13-(K13*J13/100) | M13: =ROUND(L13/1.11, 2) | N13: =SUM(P13:CD13) | O13: =COUNTIF(P13:CD13,">0") | P13: 0 | Q13: 0 | R13: 0 | S13: 0 | T13: 0 | U13: 0 | V13: 0 | W13: 0 | X13: 0 | Y13: 0 | Z13: 0 | AA13: 0 | AB13: 0 | AC13: 0 | AD13: 0 | AE13: 0 | AF13: 0 | AG13: 0 | AH13: 0 | AI13: 0 | AJ13: 0 | AK13: 0 | AL13: 0 | AM13: 0 | AN13: 0 | AO13: 0 | AP13: 0 | AQ13: 0 | AR13: 0 | AS13: 0 | AT13: 0 | AU13: 0 | AV13: 0 | AW13: 0 | AX13: 0 | AY13: 0 | AZ13: 0 | BA13: 0 | BB13: 0 | BC13: 0 | BD13: 0 | BE13: 0 | BF13: 0 | BG13: 0 | BH13: 0 | BI13: 0 | BJ13: 0 | BK13: 0 | BL13: 0 | BM13: 0 | BN13: 0 | BO13: 0 | BP13: 0 | BQ13: 0 | BR13: 0 | BS13: 0 | BT13: 0 | BU13: 0 | BV13: 0 | BW13: 0 | BX13: 0 | BY13: 0 | BZ13: 0 | CA13: 0 | CB13: 0 | CC13: 0 | CD13: 0
A14: 12 | B14: 2026-07-04 | C14: 71306761 | D14: SMTR-01 | E14: (1881578585)WARUNG SAYUR ASEP | F14: WARUNG NOO | G14: WARUNG NOO | H14: Consignment | J14: 10 | K14: =(P2*P14)+(Q2*Q14)+(R2*R14)+(S2*S14)+(T2*T14)+(U2*U14)+(V2*V14)+(W2*W14)+(X2*X14)+(Y2*Y14)+(Z2*Z14)+(AA2*AA14)+(AB2*AB14)+(AC2*AC14)+(AD2*AD14)+(AE2*AE14)+(AF2*AF14)+(AG2*AG14)+(AH2*AH14)+(AI2*AI14)+(AJ2*AJ14)+(AK2*AK14)+(AL2*AL14)+(AM2*AM14)+(AN2*AN14)+(AO2*AO14)+(AP2*AP14)+(AQ2*AQ14)+(AR2*AR14)+(AS2*AS14)+(AT2*AT14)+(AU2*AU14)+(AV2*AV14)+(AW2*AW14)+(AX2*AX14)+(AY2*AY14)+(AZ2*AZ14)+(BA2*BA14)+(BB2*BB14)+(BC2*BC14)+(BD2*BD14)+(BE2*BE14)+(BF2*BF14)+(BG2*BG14)+(BH2*BH14)+(BI2*BI14)+(BJ2*BJ14)+(BK2*BK14)+(BL2*BL14)+(BM2*BM14)+(BN2*BN14)+(BO2*BO14)+(BP2*BP14)+(BQ2*BQ14)+(BR2*BR14)+(BS2*BS14)+(BT2*BT14)+(BU2*BU14)+(BV2*BV14)+(BW2*BW14)+(BX2*BX14)+(BY2*BY14)+(BZ2*BZ14)+(CA2*CA14)+(CB2*CB14)+(CC2*CC14)+(CD2*CD14) | L14: =K14-(K14*J14/100) | M14: =ROUND(L14/1.11, 2) | N14: =SUM(P14:CD14) | O14: =COUNTIF(P14:CD14,">0") | P14: 0 | Q14: 0 | R14: 0 | S14: 0 | T14: 0 | U14: 0 | V14: 0 | W14: 0 | X14: 0 | Y14: 0 | Z14: 0 | AA14: 0 | AB14: 0 | AC14: 0 | AD14: 0 | AE14: 0 | AF14: 0 | AG14: 0 | AH14: 0 | AI14: 0 | AJ14: 0 | AK14: 0 | AL14: 0 | AM14: 0 | AN14: 0 | AO14: 0 | AP14: 0 | AQ14: 0 | AR14: 0 | AS14: 0 | AT14: 0 | AU14: 0 | AV14: 0 | AW14: 0 | AX14: 0 | AY14: 0 | AZ14: 0 | BA14: 0 | BB14: 0 | BC14: 0 | BD14: 0 | BE14: 0 | BF14: 0 | BG14: 0 | BH14: 0 | BI14: 0 | BJ14: 0 | BK14: 0 | BL14: 0 | BM14: 0 | BN14: 0 | BO14: 0 | BP14: 0 | BQ14: 0 | BR14: 0 | BS14: 0 | BT14: 0 | BU14: 0 | BV14: 0 | BW14: 0 | BX14: 0 | BY14: 0 | BZ14: 0 | CA14: 0 | CB14: 0 | CC14: 0 | CD14: 0
A15: 13 | B15: 2026-07-04 | C15: 71306761 | D15: SMTR-01 | E15: (1881579074)kantin RS Husada | F15: RUMAH SAKIT | G15: LAYANAN KESEHATAN | H15: Consignment | J15: 10 | K15: =(P2*P15)+(Q2*Q15)+(R2*R15)+(S2*S15)+(T2*T15)+(U2*U15)+(V2*V15)+(W2*W15)+(X2*X15)+(Y2*Y15)+(Z2*Z15)+(AA2*AA15)+(AB2*AB15)+(AC2*AC15)+(AD2*AD15)+(AE2*AE15)+(AF2*AF15)+(AG2*AG15)+(AH2*AH15)+(AI2*AI15)+(AJ2*AJ15)+(AK2*AK15)+(AL2*AL15)+(AM2*AM15)+(AN2*AN15)+(AO2*AO15)+(AP2*AP15)+(AQ2*AQ15)+(AR2*AR15)+(AS2*AS15)+(AT2*AT15)+(AU2*AU15)+(AV2*AV15)+(AW2*AW15)+(AX2*AX15)+(AY2*AY15)+(AZ2*AZ15)+(BA2*BA15)+(BB2*BB15)+(BC2*BC15)+(BD2*BD15)+(BE2*BE15)+(BF2*BF15)+(BG2*BG15)+(BH2*BH15)+(BI2*BI15)+(BJ2*BJ15)+(BK2*BK15)+(BL2*BL15)+(BM2*BM15)+(BN2*BN15)+(BO2*BO15)+(BP2*BP15)+(BQ2*BQ15)+(BR2*BR15)+(BS2*BS15)+(BT2*BT15)+(BU2*BU15)+(BV2*BV15)+(BW2*BW15)+(BX2*BX15)+(BY2*BY15)+(BZ2*BZ15)+(CA2*CA15)+(CB2*CB15)+(CC2*CC15)+(CD2*CD15) | L15: =K15-(K15*J15/100) | M15: =ROUND(L15/1.11, 2) | N15: =SUM(P15:CD15) | O15: =COUNTIF(P15:CD15,">0") | P15: 0 | Q15: 0 | R15: 0 | S15: 0 | T15: 0 | U15: 0 | V15: 0 | W15: 0 | X15: 0 | Y15: 0 | Z15: 0 | AA15: 0 | AB15: 0 | AC15: 0 | AD15: 0 | AE15: 0 | AF15: 0 | AG15: 0 | AH15: 0 | AI15: 0 | AJ15: 0 | AK15: 0 | AL15: 0 | AM15: 0 | AN15: 0 | AO15: 0 | AP15: 0 | AQ15: 0 | AR15: 0 | AS15: 0 | AT15: 0 | AU15: 0 | AV15: 0 | AW15: 0 | AX15: 0 | AY15: 0 | AZ15: 0 | BA15: 0 | BB15: 0 | BC15: 0 | BD15: 0 | BE15: 0 | BF15: 0 | BG15: 0 | BH15: 0 | BI15: 0 | BJ15: 0 | BK15: 0 | BL15: 0 | BM15: 0 | BN15: 0 | BO15: 0 | BP15: 0 | BQ15: 0 | BR15: 0 | BS15: 0 | BT15: 0 | BU15: 0 | BV15: 0 | BW15: 0 | BX15: 0 | BY15: 0 | BZ15: 0 | CA15: 0 | CB15: 0 | CC15: 0 | CD15: 0
A16: 14 | B16: 2026-07-04 | C16: 71306761 | D16: SMTR-01 | E16: (1881579637)KANTIN BU ELI | F16: WARUNG NOO | G16: WARUNG NOO | H16: Consignment | J16: 10 | K16: =(P2*P16)+(Q2*Q16)+(R2*R16)+(S2*S16)+(T2*T16)+(U2*U16)+(V2*V16)+(W2*W16)+(X2*X16)+(Y2*Y16)+(Z2*Z16)+(AA2*AA16)+(AB2*AB16)+(AC2*AC16)+(AD2*AD16)+(AE2*AE16)+(AF2*AF16)+(AG2*AG16)+(AH2*AH16)+(AI2*AI16)+(AJ2*AJ16)+(AK2*AK16)+(AL2*AL16)+(AM2*AM16)+(AN2*AN16)+(AO2*AO16)+(AP2*AP16)+(AQ2*AQ16)+(AR2*AR16)+(AS2*AS16)+(AT2*AT16)+(AU2*AU16)+(AV2*AV16)+(AW2*AW16)+(AX2*AX16)+(AY2*AY16)+(AZ2*AZ16)+(BA2*BA16)+(BB2*BB16)+(BC2*BC16)+(BD2*BD16)+(BE2*BE16)+(BF2*BF16)+(BG2*BG16)+(BH2*BH16)+(BI2*BI16)+(BJ2*BJ16)+(BK2*BK16)+(BL2*BL16)+(BM2*BM16)+(BN2*BN16)+(BO2*BO16)+(BP2*BP16)+(BQ2*BQ16)+(BR2*BR16)+(BS2*BS16)+(BT2*BT16)+(BU2*BU16)+(BV2*BV16)+(BW2*BW16)+(BX2*BX16)+(BY2*BY16)+(BZ2*BZ16)+(CA2*CA16)+(CB2*CB16)+(CC2*CC16)+(CD2*CD16) | L16: =K16-(K16*J16/100) | M16: =ROUND(L16/1.11, 2) | N16: =SUM(P16:CD16) | O16: =COUNTIF(P16:CD16,">0") | P16: 0 | Q16: 0 | R16: 0 | S16: 0 | T16: 0 | U16: 0 | V16: 0 | W16: 0 | X16: 0 | Y16: 0 | Z16: 0 | AA16: 0 | AB16: 0 | AC16: 0 | AD16: 0 | AE16: 0 | AF16: 0 | AG16: 0 | AH16: 0 | AI16: 0 | AJ16: 0 | AK16: 0 | AL16: 0 | AM16: 0 | AN16: 0 | AO16: 0 | AP16: 0 | AQ16: 0 | AR16: 0 | AS16: 0 | AT16: 0 | AU16: 0 | AV16: 0 | AW16: 0 | AX16: 0 | AY16: 0 | AZ16: 0 | BA16: 0 | BB16: 0 | BC16: 0 | BD16: 0 | BE16: 0 | BF16: 0 | BG16: 0 | BH16: 0 | BI16: 0 | BJ16: 0 | BK16: 0 | BL16: 0 | BM16: 0 | BN16: 0 | BO16: 0 | BP16: 0 | BQ16: 0 | BR16: 0 | BS16: 0 | BT16: 0 | BU16: 0 | BV16: 0 | BW16: 0 | BX16: 0 | BY16: 0 | BZ16: 0 | CA16: 0 | CB16: 0 | CC16: 0 | CD16: 0
A17: 15 | B17: 2026-07-04 | C17: 71306761 | D17: SMTR-01 | E17: (1881579647)WARKOP JAMAL | F17: WARUNG NOO | G17: WARUNG NOO | H17: Consignment | J17: 10 | K17: =(P2*P17)+(Q2*Q17)+(R2*R17)+(S2*S17)+(T2*T17)+(U2*U17)+(V2*V17)+(W2*W17)+(X2*X17)+(Y2*Y17)+(Z2*Z17)+(AA2*AA17)+(AB2*AB17)+(AC2*AC17)+(AD2*AD17)+(AE2*AE17)+(AF2*AF17)+(AG2*AG17)+(AH2*AH17)+(AI2*AI17)+(AJ2*AJ17)+(AK2*AK17)+(AL2*AL17)+(AM2*AM17)+(AN2*AN17)+(AO2*AO17)+(AP2*AP17)+(AQ2*AQ17)+(AR2*AR17)+(AS2*AS17)+(AT2*AT17)+(AU2*AU17)+(AV2*AV17)+(AW2*AW17)+(AX2*AX17)+(AY2*AY17)+(AZ2*AZ17)+(BA2*BA17)+(BB2*BB17)+(BC2*BC17)+(BD2*BD17)+(BE2*BE17)+(BF2*BF17)+(BG2*BG17)+(BH2*BH17)+(BI2*BI17)+(BJ2*BJ17)+(BK2*BK17)+(BL2*BL17)+(BM2*BM17)+(BN2*BN17)+(BO2*BO17)+(BP2*BP17)+(BQ2*BQ17)+(BR2*BR17)+(BS2*BS17)+(BT2*BT17)+(BU2*BU17)+(BV2*BV17)+(BW2*BW17)+(BX2*BX17)+(BY2*BY17)+(BZ2*BZ17)+(CA2*CA17)+(CB2*CB17)+(CC2*CC17)+(CD2*CD17) | L17: =K17-(K17*J17/100) | M17: =ROUND(L17/1.11, 2) | N17: =SUM(P17:CD17) | O17: =COUNTIF(P17:CD17,">0") | P17: 0 | Q17: 0 | R17: 0 | S17: 0 | T17: 0 | U17: 0 | V17: 0 | W17: 0 | X17: 0 | Y17: 0 | Z17: 0 | AA17: 0 | AB17: 0 | AC17: 0 | AD17: 0 | AE17: 0 | AF17: 0 | AG17: 0 | AH17: 0 | AI17: 0 | AJ17: 0 | AK17: 0 | AL17: 0 | AM17: 0 | AN17: 0 | AO17: 0 | AP17: 0 | AQ17: 0 | AR17: 0 | AS17: 0 | AT17: 0 | AU17: 0 | AV17: 0 | AW17: 0 | AX17: 0 | AY17: 0 | AZ17: 0 | BA17: 0 | BB17: 0 | BC17: 0 | BD17: 0 | BE17: 0 | BF17: 0 | BG17: 0 | BH17: 0 | BI17: 0 | BJ17: 0 | BK17: 0 | BL17: 0 | BM17: 0 | BN17: 0 | BO17: 0 | BP17: 0 | BQ17: 0 | BR17: 0 | BS17: 0 | BT17: 0 | BU17: 0 | BV17: 0 | BW17: 0 | BX17: 0 | BY17: 0 | BZ17: 0 | CA17: 0 | CB17: 0 | CC17: 0 | CD17: 0
A18: 16 | B18: 2026-07-04 | C18: 71306761 | D18: SMTR-01 | E18: (1881579659)TOKO SAIT | F18: WARUNG NOO | G18: WARUNG NOO | H18: Consignment | J18: 10 | K18: =(P2*P18)+(Q2*Q18)+(R2*R18)+(S2*S18)+(T2*T18)+(U2*U18)+(V2*V18)+(W2*W18)+(X2*X18)+(Y2*Y18)+(Z2*Z18)+(AA2*AA18)+(AB2*AB18)+(AC2*AC18)+(AD2*AD18)+(AE2*AE18)+(AF2*AF18)+(AG2*AG18)+(AH2*AH18)+(AI2*AI18)+(AJ2*AJ18)+(AK2*AK18)+(AL2*AL18)+(AM2*AM18)+(AN2*AN18)+(AO2*AO18)+(AP2*AP18)+(AQ2*AQ18)+(AR2*AR18)+(AS2*AS18)+(AT2*AT18)+(AU2*AU18)+(AV2*AV18)+(AW2*AW18)+(AX2*AX18)+(AY2*AY18)+(AZ2*AZ18)+(BA2*BA18)+(BB2*BB18)+(BC2*BC18)+(BD2*BD18)+(BE2*BE18)+(BF2*BF18)+(BG2*BG18)+(BH2*BH18)+(BI2*BI18)+(BJ2*BJ18)+(BK2*BK18)+(BL2*BL18)+(BM2*BM18)+(BN2*BN18)+(BO2*BO18)+(BP2*BP18)+(BQ2*BQ18)+(BR2*BR18)+(BS2*BS18)+(BT2*BT18)+(BU2*BU18)+(BV2*BV18)+(BW2*BW18)+(BX2*BX18)+(BY2*BY18)+(BZ2*BZ18)+(CA2*CA18)+(CB2*CB18)+(CC2*CC18)+(CD2*CD18) | L18: =K18-(K18*J18/100) | M18: =ROUND(L18/1.11, 2) | N18: =SUM(P18:CD18) | O18: =COUNTIF(P18:CD18,">0") | P18: 0 | Q18: 0 | R18: 0 | S18: 0 | T18: 0 | U18: 0 | V18: 0 | W18: 0 | X18: 0 | Y18: 0 | Z18: 0 | AA18: 0 | AB18: 0 | AC18: 0 | AD18: 0 | AE18: 0 | AF18: 0 | AG18: 0 | AH18: 0 | AI18: 0 | AJ18: 0 | AK18: 0 | AL18: 0 | AM18: 0 | AN18: 0 | AO18: 0 | AP18: 0 | AQ18: 0 | AR18: 0 | AS18: 0 | AT18: 0 | AU18: 0 | AV18: 0 | AW18: 0 | AX18: 0 | AY18: 0 | AZ18: 0 | BA18: 0 | BB18: 0 | BC18: 0 | BD18: 0 | BE18: 0 | BF18: 0 | BG18: 0 | BH18: 0 | BI18: 0 | BJ18: 0 | BK18: 0 | BL18: 0 | BM18: 0 | BN18: 0 | BO18: 0 | BP18: 0 | BQ18: 0 | BR18: 0 | BS18: 0 | BT18: 0 | BU18: 0 | BV18: 0 | BW18: 0 | BX18: 0 | BY18: 0 | BZ18: 0 | CA18: 0 | CB18: 0 | CC18: 0 | CD18: 0
A19: 17 | B19: 2026-07-04 | C19: 71306761 | D19: SMTR-01 | E19: (1881581001)TOKO ALIKA | F19: WARUNG NOO | G19: WARUNG NOO | H19: Consignment | J19: 10 | K19: =(P2*P19)+(Q2*Q19)+(R2*R19)+(S2*S19)+(T2*T19)+(U2*U19)+(V2*V19)+(W2*W19)+(X2*X19)+(Y2*Y19)+(Z2*Z19)+(AA2*AA19)+(AB2*AB19)+(AC2*AC19)+(AD2*AD19)+(AE2*AE19)+(AF2*AF19)+(AG2*AG19)+(AH2*AH19)+(AI2*AI19)+(AJ2*AJ19)+(AK2*AK19)+(AL2*AL19)+(AM2*AM19)+(AN2*AN19)+(AO2*AO19)+(AP2*AP19)+(AQ2*AQ19)+(AR2*AR19)+(AS2*AS19)+(AT2*AT19)+(AU2*AU19)+(AV2*AV19)+(AW2*AW19)+(AX2*AX19)+(AY2*AY19)+(AZ2*AZ19)+(BA2*BA19)+(BB2*BB19)+(BC2*BC19)+(BD2*BD19)+(BE2*BE19)+(BF2*BF19)+(BG2*BG19)+(BH2*BH19)+(BI2*BI19)+(BJ2*BJ19)+(BK2*BK19)+(BL2*BL19)+(BM2*BM19)+(BN2*BN19)+(BO2*BO19)+(BP2*BP19)+(BQ2*BQ19)+(BR2*BR19)+(BS2*BS19)+(BT2*BT19)+(BU2*BU19)+(BV2*BV19)+(BW2*BW19)+(BX2*BX19)+(BY2*BY19)+(BZ2*BZ19)+(CA2*CA19)+(CB2*CB19)+(CC2*CC19)+(CD2*CD19) | L19: =K19-(K19*J19/100) | M19: =ROUND(L19/1.11, 2) | N19: =SUM(P19:CD19) | O19: =COUNTIF(P19:CD19,">0") | P19: 0 | Q19: 0 | R19: 0 | S19: 0 | T19: 0 | U19: 0 | V19: 0 | W19: 0 | X19: 0 | Y19: 0 | Z19: 0 | AA19: 0 | AB19: 0 | AC19: 0 | AD19: 0 | AE19: 0 | AF19: 0 | AG19: 0 | AH19: 0 | AI19: 0 | AJ19: 0 | AK19: 0 | AL19: 0 | AM19: 0 | AN19: 0 | AO19: 0 | AP19: 0 | AQ19: 0 | AR19: 0 | AS19: 0 | AT19: 0 | AU19: 0 | AV19: 0 | AW19: 0 | AX19: 0 | AY19: 0 | AZ19: 0 | BA19: 0 | BB19: 0 | BC19: 0 | BD19: 0 | BE19: 0 | BF19: 0 | BG19: 0 | BH19: 0 | BI19: 0 | BJ19: 0 | BK19: 0 | BL19: 0 | BM19: 0 | BN19: 0 | BO19: 0 | BP19: 0 | BQ19: 0 | BR19: 0 | BS19: 0 | BT19: 0 | BU19: 0 | BV19: 0 | BW19: 0 | BX19: 0 | BY19: 0 | BZ19: 0 | CA19: 0 | CB19: 0 | CC19: 0 | CD19: 0
A20: 18 | B20: 2026-07-04 | C20: 71306761 | D20: SMTR-01 | E20: (1881581526)TOKO WIDODO | F20: WARUNG NOO | G20: WARUNG NOO | H20: Consignment | J20: 10 | K20: =(P2*P20)+(Q2*Q20)+(R2*R20)+(S2*S20)+(T2*T20)+(U2*U20)+(V2*V20)+(W2*W20)+(X2*X20)+(Y2*Y20)+(Z2*Z20)+(AA2*AA20)+(AB2*AB20)+(AC2*AC20)+(AD2*AD20)+(AE2*AE20)+(AF2*AF20)+(AG2*AG20)+(AH2*AH20)+(AI2*AI20)+(AJ2*AJ20)+(AK2*AK20)+(AL2*AL20)+(AM2*AM20)+(AN2*AN20)+(AO2*AO20)+(AP2*AP20)+(AQ2*AQ20)+(AR2*AR20)+(AS2*AS20)+(AT2*AT20)+(AU2*AU20)+(AV2*AV20)+(AW2*AW20)+(AX2*AX20)+(AY2*AY20)+(AZ2*AZ20)+(BA2*BA20)+(BB2*BB20)+(BC2*BC20)+(BD2*BD20)+(BE2*BE20)+(BF2*BF20)+(BG2*BG20)+(BH2*BH20)+(BI2*BI20)+(BJ2*BJ20)+(BK2*BK20)+(BL2*BL20)+(BM2*BM20)+(BN2*BN20)+(BO2*BO20)+(BP2*BP20)+(BQ2*BQ20)+(BR2*BR20)+(BS2*BS20)+(BT2*BT20)+(BU2*BU20)+(BV2*BV20)+(BW2*BW20)+(BX2*BX20)+(BY2*BY20)+(BZ2*BZ20)+(CA2*CA20)+(CB2*CB20)+(CC2*CC20)+(CD2*CD20) | L20: =K20-(K20*J20/100) | M20: =ROUND(L20/1.11, 2) | N20: =SUM(P20:CD20) | O20: =COUNTIF(P20:CD20,">0") | P20: 0 | Q20: 0 | R20: 0 | S20: 0 | T20: 0 | U20: 0 | V20: 0 | W20: 0 | X20: 0 | Y20: 0 | Z20: 0 | AA20: 0 | AB20: 0 | AC20: 0 | AD20: 0 | AE20: 0 | AF20: 0 | AG20: 0 | AH20: 0 | AI20: 0 | AJ20: 0 | AK20: 0 | AL20: 0 | AM20: 0 | AN20: 0 | AO20: 0 | AP20: 0 | AQ20: 0 | AR20: 0 | AS20: 0 | AT20: 0 | AU20: 0 | AV20: 0 | AW20: 0 | AX20: 0 | AY20: 0 | AZ20: 0 | BA20: 0 | BB20: 0 | BC20: 0 | BD20: 0 | BE20: 0 | BF20: 0 | BG20: 0 | BH20: 0 | BI20: 0 | BJ20: 0 | BK20: 0 | BL20: 0 | BM20: 0 | BN20: 0 | BO20: 0 | BP20: 0 | BQ20: 0 | BR20: 0 | BS20: 0 | BT20: 0 | BU20: 0 | BV20: 0 | BW20: 0 | BX20: 0 | BY20: 0 | BZ20: 0 | CA20: 0 | CB20: 0 | CC20: 0 | CD20: 0
A21: 19 | B21: 2026-07-04 | C21: 71306761 | D21: SMTR-01 | E21: (1881582966)TOKO ARDIANSYAH | F21: WARUNG NOO | G21: WARUNG NOO | H21: Consignment | J21: 10 | K21: =(P2*P21)+(Q2*Q21)+(R2*R21)+(S2*S21)+(T2*T21)+(U2*U21)+(V2*V21)+(W2*W21)+(X2*X21)+(Y2*Y21)+(Z2*Z21)+(AA2*AA21)+(AB2*AB21)+(AC2*AC21)+(AD2*AD21)+(AE2*AE21)+(AF2*AF21)+(AG2*AG21)+(AH2*AH21)+(AI2*AI21)+(AJ2*AJ21)+(AK2*AK21)+(AL2*AL21)+(AM2*AM21)+(AN2*AN21)+(AO2*AO21)+(AP2*AP21)+(AQ2*AQ21)+(AR2*AR21)+(AS2*AS21)+(AT2*AT21)+(AU2*AU21)+(AV2*AV21)+(AW2*AW21)+(AX2*AX21)+(AY2*AY21)+(AZ2*AZ21)+(BA2*BA21)+(BB2*BB21)+(BC2*BC21)+(BD2*BD21)+(BE2*BE21)+(BF2*BF21)+(BG2*BG21)+(BH2*BH21)+(BI2*BI21)+(BJ2*BJ21)+(BK2*BK21)+(BL2*BL21)+(BM2*BM21)+(BN2*BN21)+(BO2*BO21)+(BP2*BP21)+(BQ2*BQ21)+(BR2*BR21)+(BS2*BS21)+(BT2*BT21)+(BU2*BU21)+(BV2*BV21)+(BW2*BW21)+(BX2*BX21)+(BY2*BY21)+(BZ2*BZ21)+(CA2*CA21)+(CB2*CB21)+(CC2*CC21)+(CD2*CD21) | L21: =K21-(K21*J21/100) | M21: =ROUND(L21/1.11, 2) | N21: =SUM(P21:CD21) | O21: =COUNTIF(P21:CD21,">0") | P21: 0 | Q21: 0 | R21: 0 | S21: 0 | T21: 0 | U21: 0 | V21: 0 | W21: 0 | X21: 0 | Y21: 0 | Z21: 0 | AA21: 0 | AB21: 0 | AC21: 0 | AD21: 0 | AE21: 0 | AF21: 0 | AG21: 0 | AH21: 0 | AI21: 0 | AJ21: 0 | AK21: 0 | AL21: 0 | AM21: 0 | AN21: 0 | AO21: 0 | AP21: 0 | AQ21: 0 | AR21: 0 | AS21: 0 | AT21: 0 | AU21: 0 | AV21: 0 | AW21: 0 | AX21: 0 | AY21: 0 | AZ21: 0 | BA21: 0 | BB21: 0 | BC21: 0 | BD21: 0 | BE21: 0 | BF21: 0 | BG21: 0 | BH21: 0 | BI21: 0 | BJ21: 0 | BK21: 0 | BL21: 0 | BM21: 0 | BN21: 0 | BO21: 0 | BP21: 0 | BQ21: 0 | BR21: 0 | BS21: 0 | BT21: 0 | BU21: 0 | BV21: 0 | BW21: 0 | BX21: 0 | BY21: 0 | BZ21: 0 | CA21: 0 | CB21: 0 | CC21: 0 | CD21: 0
A22: 20 | B22: 2026-07-04 | C22: 71306761 | D22: SMTR-01 | E22: (1881589033)PIONA TOKO | F22: WARUNG NOO | G22: WARUNG NOO | H22: Consignment | J22: 10 | K22: =(P2*P22)+(Q2*Q22)+(R2*R22)+(S2*S22)+(T2*T22)+(U2*U22)+(V2*V22)+(W2*W22)+(X2*X22)+(Y2*Y22)+(Z2*Z22)+(AA2*AA22)+(AB2*AB22)+(AC2*AC22)+(AD2*AD22)+(AE2*AE22)+(AF2*AF22)+(AG2*AG22)+(AH2*AH22)+(AI2*AI22)+(AJ2*AJ22)+(AK2*AK22)+(AL2*AL22)+(AM2*AM22)+(AN2*AN22)+(AO2*AO22)+(AP2*AP22)+(AQ2*AQ22)+(AR2*AR22)+(AS2*AS22)+(AT2*AT22)+(AU2*AU22)+(AV2*AV22)+(AW2*AW22)+(AX2*AX22)+(AY2*AY22)+(AZ2*AZ22)+(BA2*BA22)+(BB2*BB22)+(BC2*BC22)+(BD2*BD22)+(BE2*BE22)+(BF2*BF22)+(BG2*BG22)+(BH2*BH22)+(BI2*BI22)+(BJ2*BJ22)+(BK2*BK22)+(BL2*BL22)+(BM2*BM22)+(BN2*BN22)+(BO2*BO22)+(BP2*BP22)+(BQ2*BQ22)+(BR2*BR22)+(BS2*BS22)+(BT2*BT22)+(BU2*BU22)+(BV2*BV22)+(BW2*BW22)+(BX2*BX22)+(BY2*BY22)+(BZ2*BZ22)+(CA2*CA22)+(CB2*CB22)+(CC2*CC22)+(CD2*CD22) | L22: =K22-(K22*J22/100) | M22: =ROUND(L22/1.11, 2) | N22: =SUM(P22:CD22) | O22: =COUNTIF(P22:CD22,">0") | P22: 0 | Q22: 0 | R22: 0 | S22: 0 | T22: 0 | U22: 0 | V22: 0 | W22: 0 | X22: 0 | Y22: 0 | Z22: 0 | AA22: 0 | AB22: 0 | AC22: 0 | AD22: 0 | AE22: 0 | AF22: 0 | AG22: 0 | AH22: 0 | AI22: 0 | AJ22: 0 | AK22: 0 | AL22: 0 | AM22: 0 | AN22: 0 | AO22: 0 | AP22: 0 | AQ22: 0 | AR22: 0 | AS22: 0 | AT22: 0 | AU22: 0 | AV22: 0 | AW22: 0 | AX22: 0 | AY22: 0 | AZ22: 0 | BA22: 0 | BB22: 0 | BC22: 0 | BD22: 0 | BE22: 0 | BF22: 0 | BG22: 0 | BH22: 0 | BI22: 0 | BJ22: 0 | BK22: 0 | BL22: 0 | BM22: 0 | BN22: 0 | BO22: 0 | BP22: 0 | BQ22: 0 | BR22: 0 | BS22: 0 | BT22: 0 | BU22: 0 | BV22: 0 | BW22: 0 | BX22: 0 | BY22: 0 | BZ22: 0 | CA22: 0 | CB22: 0 | CC22: 0 | CD22: 0
A23: 21 | B23: 2026-07-04 | C23: 71306762 | D23: SMTR_02 | E23: (1881578437)OSIEN TOKO | F23: WARUNG NOO | G23: WARUNG NOO | H23: Consignment | J23: 10 | K23: =(P2*P23)+(Q2*Q23)+(R2*R23)+(S2*S23)+(T2*T23)+(U2*U23)+(V2*V23)+(W2*W23)+(X2*X23)+(Y2*Y23)+(Z2*Z23)+(AA2*AA23)+(AB2*AB23)+(AC2*AC23)+(AD2*AD23)+(AE2*AE23)+(AF2*AF23)+(AG2*AG23)+(AH2*AH23)+(AI2*AI23)+(AJ2*AJ23)+(AK2*AK23)+(AL2*AL23)+(AM2*AM23)+(AN2*AN23)+(AO2*AO23)+(AP2*AP23)+(AQ2*AQ23)+(AR2*AR23)+(AS2*AS23)+(AT2*AT23)+(AU2*AU23)+(AV2*AV23)+(AW2*AW23)+(AX2*AX23)+(AY2*AY23)+(AZ2*AZ23)+(BA2*BA23)+(BB2*BB23)+(BC2*BC23)+(BD2*BD23)+(BE2*BE23)+(BF2*BF23)+(BG2*BG23)+(BH2*BH23)+(BI2*BI23)+(BJ2*BJ23)+(BK2*BK23)+(BL2*BL23)+(BM2*BM23)+(BN2*BN23)+(BO2*BO23)+(BP2*BP23)+(BQ2*BQ23)+(BR2*BR23)+(BS2*BS23)+(BT2*BT23)+(BU2*BU23)+(BV2*BV23)+(BW2*BW23)+(BX2*BX23)+(BY2*BY23)+(BZ2*BZ23)+(CA2*CA23)+(CB2*CB23)+(CC2*CC23)+(CD2*CD23) | L23: =K23-(K23*J23/100) | M23: =ROUND(L23/1.11, 2) | N23: =SUM(P23:CD23) | O23: =COUNTIF(P23:CD23,">0") | P23: 0 | Q23: 0 | R23: 0 | S23: 0 | T23: 0 | U23: 0 | V23: 0 | W23: 0 | X23: 0 | Y23: 0 | Z23: 0 | AA23: 0 | AB23: 0 | AC23: 0 | AD23: 0 | AE23: 0 | AF23: 0 | AG23: 0 | AH23: 0 | AI23: 0 | AJ23: 0 | AK23: 0 | AL23: 0 | AM23: 0 | AN23: 0 | AO23: 0 | AP23: 0 | AQ23: 0 | AR23: 0 | AS23: 0 | AT23: 0 | AU23: 0 | AV23: 0 | AW23: 0 | AX23: 0 | AY23: 0 | AZ23: 0 | BA23: 0 | BB23: 0 | BC23: 0 | BD23: 0 | BE23: 0 | BF23: 0 | BG23: 0 | BH23: 0 | BI23: 0 | BJ23: 0 | BK23: 0 | BL23: 0 | BM23: 0 | BN23: 0 | BO23: 0 | BP23: 0 | BQ23: 0 | BR23: 0 | BS23: 0 | BT23: 0 | BU23: 0 | BV23: 0 | BW23: 0 | BX23: 0 | BY23: 0 | BZ23: 0 | CA23: 0 | CB23: 0 | CC23: 0 | CD23: 0
A24: 22 | B24: 2026-07-04 | C24: 71306762 | D24: SMTR_02 | E24: (1881578438)SRC 99 TOKO | F24: WARUNG NOO | G24: WARUNG NOO | H24: Consignment | J24: 10 | K24: =(P2*P24)+(Q2*Q24)+(R2*R24)+(S2*S24)+(T2*T24)+(U2*U24)+(V2*V24)+(W2*W24)+(X2*X24)+(Y2*Y24)+(Z2*Z24)+(AA2*AA24)+(AB2*AB24)+(AC2*AC24)+(AD2*AD24)+(AE2*AE24)+(AF2*AF24)+(AG2*AG24)+(AH2*AH24)+(AI2*AI24)+(AJ2*AJ24)+(AK2*AK24)+(AL2*AL24)+(AM2*AM24)+(AN2*AN24)+(AO2*AO24)+(AP2*AP24)+(AQ2*AQ24)+(AR2*AR24)+(AS2*AS24)+(AT2*AT24)+(AU2*AU24)+(AV2*AV24)+(AW2*AW24)+(AX2*AX24)+(AY2*AY24)+(AZ2*AZ24)+(BA2*BA24)+(BB2*BB24)+(BC2*BC24)+(BD2*BD24)+(BE2*BE24)+(BF2*BF24)+(BG2*BG24)+(BH2*BH24)+(BI2*BI24)+(BJ2*BJ24)+(BK2*BK24)+(BL2*BL24)+(BM2*BM24)+(BN2*BN24)+(BO2*BO24)+(BP2*BP24)+(BQ2*BQ24)+(BR2*BR24)+(BS2*BS24)+(BT2*BT24)+(BU2*BU24)+(BV2*BV24)+(BW2*BW24)+(BX2*BX24)+(BY2*BY24)+(BZ2*BZ24)+(CA2*CA24)+(CB2*CB24)+(CC2*CC24)+(CD2*CD24) | L24: =K24-(K24*J24/100) | M24: =ROUND(L24/1.11, 2) | N24: =SUM(P24:CD24) | O24: =COUNTIF(P24:CD24,">0") | P24: 0 | Q24: 0 | R24: 0 | S24: 0 | T24: 0 | U24: 0 | V24: 0 | W24: 0 | X24: 0 | Y24: 0 | Z24: 0 | AA24: 0 | AB24: 0 | AC24: 0 | AD24: 0 | AE24: 0 | AF24: 0 | AG24: 0 | AH24: 0 | AI24: 0 | AJ24: 0 | AK24: 0 | AL24: 0 | AM24: 0 | AN24: 0 | AO24: 0 | AP24: 0 | AQ24: 0 | AR24: 0 | AS24: 0 | AT24: 0 | AU24: 0 | AV24: 0 | AW24: 0 | AX24: 0 | AY24: 0 | AZ24: 0 | BA24: 0 | BB24: 0 | BC24: 0 | BD24: 0 | BE24: 0 | BF24: 0 | BG24: 0 | BH24: 0 | BI24: 0 | BJ24: 0 | BK24: 0 | BL24: 0 | BM24: 0 | BN24: 0 | BO24: 0 | BP24: 0 | BQ24: 0 | BR24: 0 | BS24: 0 | BT24: 0 | BU24: 0 | BV24: 0 | BW24: 0 | BX24: 0 | BY24: 0 | BZ24: 0 | CA24: 0 | CB24: 0 | CC24: 0 | CD24: 0
A25: 23 | B25: 2026-07-04 | C25: 71306762 | D25: SMTR_02 | E25: (1881578439)TOMMY TOKO | F25: WARUNG NOO | G25: WARUNG NOO | H25: Consignment | J25: 10 | K25: =(P2*P25)+(Q2*Q25)+(R2*R25)+(S2*S25)+(T2*T25)+(U2*U25)+(V2*V25)+(W2*W25)+(X2*X25)+(Y2*Y25)+(Z2*Z25)+(AA2*AA25)+(AB2*AB25)+(AC2*AC25)+(AD2*AD25)+(AE2*AE25)+(AF2*AF25)+(AG2*AG25)+(AH2*AH25)+(AI2*AI25)+(AJ2*AJ25)+(AK2*AK25)+(AL2*AL25)+(AM2*AM25)+(AN2*AN25)+(AO2*AO25)+(AP2*AP25)+(AQ2*AQ25)+(AR2*AR25)+(AS2*AS25)+(AT2*AT25)+(AU2*AU25)+(AV2*AV25)+(AW2*AW25)+(AX2*AX25)+(AY2*AY25)+(AZ2*AZ25)+(BA2*BA25)+(BB2*BB25)+(BC2*BC25)+(BD2*BD25)+(BE2*BE25)+(BF2*BF25)+(BG2*BG25)+(BH2*BH25)+(BI2*BI25)+(BJ2*BJ25)+(BK2*BK25)+(BL2*BL25)+(BM2*BM25)+(BN2*BN25)+(BO2*BO25)+(BP2*BP25)+(BQ2*BQ25)+(BR2*BR25)+(BS2*BS25)+(BT2*BT25)+(BU2*BU25)+(BV2*BV25)+(BW2*BW25)+(BX2*BX25)+(BY2*BY25)+(BZ2*BZ25)+(CA2*CA25)+(CB2*CB25)+(CC2*CC25)+(CD2*CD25) | L25: =K25-(K25*J25/100) | M25: =ROUND(L25/1.11, 2) | N25: =SUM(P25:CD25) | O25: =COUNTIF(P25:CD25,">0") | P25: 0 | Q25: 0 | R25: 0 | S25: 0 | T25: 0 | U25: 0 | V25: 0 | W25: 0 | X25: 0 | Y25: 0 | Z25: 0 | AA25: 0 | AB25: 0 | AC25: 0 | AD25: 0 | AE25: 0 | AF25: 0 | AG25: 0 | AH25: 0 | AI25: 0 | AJ25: 0 | AK25: 0 | AL25: 0 | AM25: 0 | AN25: 0 | AO25: 0 | AP25: 0 | AQ25: 0 | AR25: 0 | AS25: 0 | AT25: 0 | AU25: 0 | AV25: 0 | AW25: 0 | AX25: 0 | AY25: 0 | AZ25: 0 | BA25: 0 | BB25: 0 | BC25: 0 | BD25: 0 | BE25: 0 | BF25: 0 | BG25: 0 | BH25: 0 | BI25: 0 | BJ25: 0 | BK25: 0 | BL25: 0 | BM25: 0 | BN25: 0 | BO25: 0 | BP25: 0 | BQ25: 0 | BR25: 0 | BS25: 0 | BT25: 0 | BU25: 0 | BV25: 0 | BW25: 0 | BX25: 0 | BY25: 0 | BZ25: 0 | CA25: 0 | CB25: 0 | CC25: 0 | CD25: 0
A26: 24 | B26: 2026-07-04 | C26: 71306762 | D26: SMTR_02 | E26: (1881578440)TOKO IBRENA | F26: WARUNG NOO | G26: WARUNG NOO | H26: Consignment | J26: 10 | K26: =(P2*P26)+(Q2*Q26)+(R2*R26)+(S2*S26)+(T2*T26)+(U2*U26)+(V2*V26)+(W2*W26)+(X2*X26)+(Y2*Y26)+(Z2*Z26)+(AA2*AA26)+(AB2*AB26)+(AC2*AC26)+(AD2*AD26)+(AE2*AE26)+(AF2*AF26)+(AG2*AG26)+(AH2*AH26)+(AI2*AI26)+(AJ2*AJ26)+(AK2*AK26)+(AL2*AL26)+(AM2*AM26)+(AN2*AN26)+(AO2*AO26)+(AP2*AP26)+(AQ2*AQ26)+(AR2*AR26)+(AS2*AS26)+(AT2*AT26)+(AU2*AU26)+(AV2*AV26)+(AW2*AW26)+(AX2*AX26)+(AY2*AY26)+(AZ2*AZ26)+(BA2*BA26)+(BB2*BB26)+(BC2*BC26)+(BD2*BD26)+(BE2*BE26)+(BF2*BF26)+(BG2*BG26)+(BH2*BH26)+(BI2*BI26)+(BJ2*BJ26)+(BK2*BK26)+(BL2*BL26)+(BM2*BM26)+(BN2*BN26)+(BO2*BO26)+(BP2*BP26)+(BQ2*BQ26)+(BR2*BR26)+(BS2*BS26)+(BT2*BT26)+(BU2*BU26)+(BV2*BV26)+(BW2*BW26)+(BX2*BX26)+(BY2*BY26)+(BZ2*BZ26)+(CA2*CA26)+(CB2*CB26)+(CC2*CC26)+(CD2*CD26) | L26: =K26-(K26*J26/100) | M26: =ROUND(L26/1.11, 2) | N26: =SUM(P26:CD26) | O26: =COUNTIF(P26:CD26,">0") | P26: 0 | Q26: 0 | R26: 0 | S26: 0 | T26: 0 | U26: 0 | V26: 0 | W26: 0 | X26: 0 | Y26: 0 | Z26: 0 | AA26: 0 | AB26: 0 | AC26: 0 | AD26: 0 | AE26: 0 | AF26: 0 | AG26: 0 | AH26: 0 | AI26: 0 | AJ26: 0 | AK26: 0 | AL26: 0 | AM26: 0 | AN26: 0 | AO26: 0 | AP26: 0 | AQ26: 0 | AR26: 0 | AS26: 0 | AT26: 0 | AU26: 0 | AV26: 0 | AW26: 0 | AX26: 0 | AY26: 0 | AZ26: 0 | BA26: 0 | BB26: 0 | BC26: 0 | BD26: 0 | BE26: 0 | BF26: 0 | BG26: 0 | BH26: 0 | BI26: 0 | BJ26: 0 | BK26: 0 | BL26: 0 | BM26: 0 | BN26: 0 | BO26: 0 | BP26: 0 | BQ26: 0 | BR26: 0 | BS26: 0 | BT26: 0 | BU26: 0 | BV26: 0 | BW26: 0 | BX26: 0 | BY26: 0 | BZ26: 0 | CA26: 0 | CB26: 0 | CC26: 0 | CD26: 0
A27: 25 | B27: 2026-07-04 | C27: 71306762 | D27: SMTR_02 | E27: (1881578443)IBU YUYUN WARUNG | F27: WARUNG NOO | G27: WARUNG NOO | H27: Consignment | J27: 10 | K27: =(P2*P27)+(Q2*Q27)+(R2*R27)+(S2*S27)+(T2*T27)+(U2*U27)+(V2*V27)+(W2*W27)+(X2*X27)+(Y2*Y27)+(Z2*Z27)+(AA2*AA27)+(AB2*AB27)+(AC2*AC27)+(AD2*AD27)+(AE2*AE27)+(AF2*AF27)+(AG2*AG27)+(AH2*AH27)+(AI2*AI27)+(AJ2*AJ27)+(AK2*AK27)+(AL2*AL27)+(AM2*AM27)+(AN2*AN27)+(AO2*AO27)+(AP2*AP27)+(AQ2*AQ27)+(AR2*AR27)+(AS2*AS27)+(AT2*AT27)+(AU2*AU27)+(AV2*AV27)+(AW2*AW27)+(AX2*AX27)+(AY2*AY27)+(AZ2*AZ27)+(BA2*BA27)+(BB2*BB27)+(BC2*BC27)+(BD2*BD27)+(BE2*BE27)+(BF2*BF27)+(BG2*BG27)+(BH2*BH27)+(BI2*BI27)+(BJ2*BJ27)+(BK2*BK27)+(BL2*BL27)+(BM2*BM27)+(BN2*BN27)+(BO2*BO27)+(BP2*BP27)+(BQ2*BQ27)+(BR2*BR27)+(BS2*BS27)+(BT2*BT27)+(BU2*BU27)+(BV2*BV27)+(BW2*BW27)+(BX2*BX27)+(BY2*BY27)+(BZ2*BZ27)+(CA2*CA27)+(CB2*CB27)+(CC2*CC27)+(CD2*CD27) | L27: =K27-(K27*J27/100) | M27: =ROUND(L27/1.11, 2) | N27: =SUM(P27:CD27) | O27: =COUNTIF(P27:CD27,">0") | P27: 0 | Q27: 0 | R27: 0 | S27: 0 | T27: 0 | U27: 0 | V27: 0 | W27: 0 | X27: 0 | Y27: 0 | Z27: 0 | AA27: 0 | AB27: 0 | AC27: 0 | AD27: 0 | AE27: 0 | AF27: 0 | AG27: 0 | AH27: 0 | AI27: 0 | AJ27: 0 | AK27: 0 | AL27: 0 | AM27: 0 | AN27: 0 | AO27: 0 | AP27: 0 | AQ27: 0 | AR27: 0 | AS27: 0 | AT27: 0 | AU27: 0 | AV27: 0 | AW27: 0 | AX27: 0 | AY27: 0 | AZ27: 0 | BA27: 0 | BB27: 0 | BC27: 0 | BD27: 0 | BE27: 0 | BF27: 0 | BG27: 0 | BH27: 0 | BI27: 0 | BJ27: 0 | BK27: 0 | BL27: 0 | BM27: 0 | BN27: 0 | BO27: 0 | BP27: 0 | BQ27: 0 | BR27: 0 | BS27: 0 | BT27: 0 | BU27: 0 | BV27: 0 | BW27: 0 | BX27: 0 | BY27: 0 | BZ27: 0 | CA27: 0 | CB27: 0 | CC27: 0 | CD27: 0
A28: 26 | B28: 2026-07-04 | C28: 71306762 | D28: SMTR_02 | E28: (1881578444)ROSDI TOKO | F28: WARUNG NOO | G28: WARUNG NOO | H28: Consignment | J28: 10 | K28: =(P2*P28)+(Q2*Q28)+(R2*R28)+(S2*S28)+(T2*T28)+(U2*U28)+(V2*V28)+(W2*W28)+(X2*X28)+(Y2*Y28)+(Z2*Z28)+(AA2*AA28)+(AB2*AB28)+(AC2*AC28)+(AD2*AD28)+(AE2*AE28)+(AF2*AF28)+(AG2*AG28)+(AH2*AH28)+(AI2*AI28)+(AJ2*AJ28)+(AK2*AK28)+(AL2*AL28)+(AM2*AM28)+(AN2*AN28)+(AO2*AO28)+(AP2*AP28)+(AQ2*AQ28)+(AR2*AR28)+(AS2*AS28)+(AT2*AT28)+(AU2*AU28)+(AV2*AV28)+(AW2*AW28)+(AX2*AX28)+(AY2*AY28)+(AZ2*AZ28)+(BA2*BA28)+(BB2*BB28)+(BC2*BC28)+(BD2*BD28)+(BE2*BE28)+(BF2*BF28)+(BG2*BG28)+(BH2*BH28)+(BI2*BI28)+(BJ2*BJ28)+(BK2*BK28)+(BL2*BL28)+(BM2*BM28)+(BN2*BN28)+(BO2*BO28)+(BP2*BP28)+(BQ2*BQ28)+(BR2*BR28)+(BS2*BS28)+(BT2*BT28)+(BU2*BU28)+(BV2*BV28)+(BW2*BW28)+(BX2*BX28)+(BY2*BY28)+(BZ2*BZ28)+(CA2*CA28)+(CB2*CB28)+(CC2*CC28)+(CD2*CD28) | L28: =K28-(K28*J28/100) | M28: =ROUND(L28/1.11, 2) | N28: =SUM(P28:CD28) | O28: =COUNTIF(P28:CD28,">0") | P28: 0 | Q28: 0 | R28: 0 | S28: 0 | T28: 0 | U28: 0 | V28: 0 | W28: 0 | X28: 0 | Y28: 0 | Z28: 0 | AA28: 0 | AB28: 0 | AC28: 0 | AD28: 0 | AE28: 0 | AF28: 0 | AG28: 0 | AH28: 0 | AI28: 0 | AJ28: 0 | AK28: 0 | AL28: 0 | AM28: 0 | AN28: 0 | AO28: 0 | AP28: 0 | AQ28: 0 | AR28: 0 | AS28: 0 | AT28: 0 | AU28: 0 | AV28: 0 | AW28: 0 | AX28: 0 | AY28: 0 | AZ28: 0 | BA28: 0 | BB28: 0 | BC28: 0 | BD28: 0 | BE28: 0 | BF28: 0 | BG28: 0 | BH28: 0 | BI28: 0 | BJ28: 0 | BK28: 0 | BL28: 0 | BM28: 0 | BN28: 0 | BO28: 0 | BP28: 0 | BQ28: 0 | BR28: 0 | BS28: 0 | BT28: 0 | BU28: 0 | BV28: 0 | BW28: 0 | BX28: 0 | BY28: 0 | BZ28: 0 | CA28: 0 | CB28: 0 | CC28: 0 | CD28: 0
A29: 27 | B29: 2026-07-04 | C29: 71306762 | D29: SMTR_02 | E29: (1881578445)KANAYA TOKO | F29: WARUNG NOO | G29: WARUNG NOO | H29: Consignment | J29: 10 | K29: =(P2*P29)+(Q2*Q29)+(R2*R29)+(S2*S29)+(T2*T29)+(U2*U29)+(V2*V29)+(W2*W29)+(X2*X29)+(Y2*Y29)+(Z2*Z29)+(AA2*AA29)+(AB2*AB29)+(AC2*AC29)+(AD2*AD29)+(AE2*AE29)+(AF2*AF29)+(AG2*AG29)+(AH2*AH29)+(AI2*AI29)+(AJ2*AJ29)+(AK2*AK29)+(AL2*AL29)+(AM2*AM29)+(AN2*AN29)+(AO2*AO29)+(AP2*AP29)+(AQ2*AQ29)+(AR2*AR29)+(AS2*AS29)+(AT2*AT29)+(AU2*AU29)+(AV2*AV29)+(AW2*AW29)+(AX2*AX29)+(AY2*AY29)+(AZ2*AZ29)+(BA2*BA29)+(BB2*BB29)+(BC2*BC29)+(BD2*BD29)+(BE2*BE29)+(BF2*BF29)+(BG2*BG29)+(BH2*BH29)+(BI2*BI29)+(BJ2*BJ29)+(BK2*BK29)+(BL2*BL29)+(BM2*BM29)+(BN2*BN29)+(BO2*BO29)+(BP2*BP29)+(BQ2*BQ29)+(BR2*BR29)+(BS2*BS29)+(BT2*BT29)+(BU2*BU29)+(BV2*BV29)+(BW2*BW29)+(BX2*BX29)+(BY2*BY29)+(BZ2*BZ29)+(CA2*CA29)+(CB2*CB29)+(CC2*CC29)+(CD2*CD29) | L29: =K29-(K29*J29/100) | M29: =ROUND(L29/1.11, 2) | N29: =SUM(P29:CD29) | O29: =COUNTIF(P29:CD29,">0") | P29: 0 | Q29: 0 | R29: 0 | S29: 0 | T29: 0 | U29: 0 | V29: 0 | W29: 0 | X29: 0 | Y29: 0 | Z29: 0 | AA29: 0 | AB29: 0 | AC29: 0 | AD29: 0 | AE29: 0 | AF29: 0 | AG29: 0 | AH29: 0 | AI29: 0 | AJ29: 0 | AK29: 0 | AL29: 0 | AM29: 0 | AN29: 0 | AO29: 0 | AP29: 0 | AQ29: 0 | AR29: 0 | AS29: 0 | AT29: 0 | AU29: 0 | AV29: 0 | AW29: 0 | AX29: 0 | AY29: 0 | AZ29: 0 | BA29: 0 | BB29: 0 | BC29: 0 | BD29: 0 | BE29: 0 | BF29: 0 | BG29: 0 | BH29: 0 | BI29: 0 | BJ29: 0 | BK29: 0 | BL29: 0 | BM29: 0 | BN29: 0 | BO29: 0 | BP29: 0 | BQ29: 0 | BR29: 0 | BS29: 0 | BT29: 0 | BU29: 0 | BV29: 0 | BW29: 0 | BX29: 0 | BY29: 0 | BZ29: 0 | CA29: 0 | CB29: 0 | CC29: 0 | CD29: 0
A30: 28 | B30: 2026-07-04 | C30: 71306762 | D30: SMTR_02 | E30: (1881578738)REPAN TOKO | F30: WARUNG NOO | G30: WARUNG NOO | H30: Consignment | J30: 10 | K30: =(P2*P30)+(Q2*Q30)+(R2*R30)+(S2*S30)+(T2*T30)+(U2*U30)+(V2*V30)+(W2*W30)+(X2*X30)+(Y2*Y30)+(Z2*Z30)+(AA2*AA30)+(AB2*AB30)+(AC2*AC30)+(AD2*AD30)+(AE2*AE30)+(AF2*AF30)+(AG2*AG30)+(AH2*AH30)+(AI2*AI30)+(AJ2*AJ30)+(AK2*AK30)+(AL2*AL30)+(AM2*AM30)+(AN2*AN30)+(AO2*AO30)+(AP2*AP30)+(AQ2*AQ30)+(AR2*AR30)+(AS2*AS30)+(AT2*AT30)+(AU2*AU30)+(AV2*AV30)+(AW2*AW30)+(AX2*AX30)+(AY2*AY30)+(AZ2*AZ30)+(BA2*BA30)+(BB2*BB30)+(BC2*BC30)+(BD2*BD30)+(BE2*BE30)+(BF2*BF30)+(BG2*BG30)+(BH2*BH30)+(BI2*BI30)+(BJ2*BJ30)+(BK2*BK30)+(BL2*BL30)+(BM2*BM30)+(BN2*BN30)+(BO2*BO30)+(BP2*BP30)+(BQ2*BQ30)+(BR2*BR30)+(BS2*BS30)+(BT2*BT30)+(BU2*BU30)+(BV2*BV30)+(BW2*BW30)+(BX2*BX30)+(BY2*BY30)+(BZ2*BZ30)+(CA2*CA30)+(CB2*CB30)+(CC2*CC30)+(CD2*CD30) | L30: =K30-(K30*J30/100) | M30: =ROUND(L30/1.11, 2) | N30: =SUM(P30:CD30) | O30: =COUNTIF(P30:CD30,">0") | P30: 0 | Q30: 0 | R30: 0 | S30: 0 | T30: 0 | U30: 0 | V30: 0 | W30: 0 | X30: 0 | Y30: 0 | Z30: 0 | AA30: 0 | AB30: 0 | AC30: 0 | AD30: 0 | AE30: 0 | AF30: 0 | AG30: 0 | AH30: 0 | AI30: 0 | AJ30: 0 | AK30: 0 | AL30: 0 | AM30: 0 | AN30: 0 | AO30: 0 | AP30: 0 | AQ30: 0 | AR30: 0 | AS30: 0 | AT30: 0 | AU30: 0 | AV30: 0 | AW30: 0 | AX30: 0 | AY30: 0 | AZ30: 0 | BA30: 0 | BB30: 0 | BC30: 0 | BD30: 0 | BE30: 0 | BF30: 0 | BG30: 0 | BH30: 0 | BI30: 0 | BJ30: 0 | BK30: 0 | BL30: 0 | BM30: 0 | BN30: 0 | BO30: 0 | BP30: 0 | BQ30: 0 | BR30: 0 | BS30: 0 | BT30: 0 | BU30: 0 | BV30: 0 | BW30: 0 | BX30: 0 | BY30: 0 | BZ30: 0 | CA30: 0 | CB30: 0 | CC30: 0 | CD30: 0
A31: 29 | B31: 2026-07-04 | C31: 71306762 | D31: SMTR_02 | E31: (1881578739)NAZWA DURIAN | F31: WARUNG NOO | G31: WARUNG NOO | H31: Consignment | J31: 10 | K31: =(P2*P31)+(Q2*Q31)+(R2*R31)+(S2*S31)+(T2*T31)+(U2*U31)+(V2*V31)+(W2*W31)+(X2*X31)+(Y2*Y31)+(Z2*Z31)+(AA2*AA31)+(AB2*AB31)+(AC2*AC31)+(AD2*AD31)+(AE2*AE31)+(AF2*AF31)+(AG2*AG31)+(AH2*AH31)+(AI2*AI31)+(AJ2*AJ31)+(AK2*AK31)+(AL2*AL31)+(AM2*AM31)+(AN2*AN31)+(AO2*AO31)+(AP2*AP31)+(AQ2*AQ31)+(AR2*AR31)+(AS2*AS31)+(AT2*AT31)+(AU2*AU31)+(AV2*AV31)+(AW2*AW31)+(AX2*AX31)+(AY2*AY31)+(AZ2*AZ31)+(BA2*BA31)+(BB2*BB31)+(BC2*BC31)+(BD2*BD31)+(BE2*BE31)+(BF2*BF31)+(BG2*BG31)+(BH2*BH31)+(BI2*BI31)+(BJ2*BJ31)+(BK2*BK31)+(BL2*BL31)+(BM2*BM31)+(BN2*BN31)+(BO2*BO31)+(BP2*BP31)+(BQ2*BQ31)+(BR2*BR31)+(BS2*BS31)+(BT2*BT31)+(BU2*BU31)+(BV2*BV31)+(BW2*BW31)+(BX2*BX31)+(BY2*BY31)+(BZ2*BZ31)+(CA2*CA31)+(CB2*CB31)+(CC2*CC31)+(CD2*CD31) | L31: =K31-(K31*J31/100) | M31: =ROUND(L31/1.11, 2) | N31: =SUM(P31:CD31) | O31: =COUNTIF(P31:CD31,">0") | P31: 0 | Q31: 0 | R31: 0 | S31: 0 | T31: 0 | U31: 0 | V31: 0 | W31: 0 | X31: 0 | Y31: 0 | Z31: 0 | AA31: 0 | AB31: 0 | AC31: 0 | AD31: 0 | AE31: 0 | AF31: 0 | AG31: 0 | AH31: 0 | AI31: 0 | AJ31: 0 | AK31: 0 | AL31: 0 | AM31: 0 | AN31: 0 | AO31: 0 | AP31: 0 | AQ31: 0 | AR31: 0 | AS31: 0 | AT31: 0 | AU31: 0 | AV31: 0 | AW31: 0 | AX31: 0 | AY31: 0 | AZ31: 0 | BA31: 0 | BB31: 0 | BC31: 0 | BD31: 0 | BE31: 0 | BF31: 0 | BG31: 0 | BH31: 0 | BI31: 0 | BJ31: 0 | BK31: 0 | BL31: 0 | BM31: 0 | BN31: 0 | BO31: 0 | BP31: 0 | BQ31: 0 | BR31: 0 | BS31: 0 | BT31: 0 | BU31: 0 | BV31: 0 | BW31: 0 | BX31: 0 | BY31: 0 | BZ31: 0 | CA31: 0 | CB31: 0 | CC31: 0 | CD31: 0
A32: 30 | B32: 2026-07-04 | C32: 71306762 | D32: SMTR_02 | E32: (1881579025)HABIBI TOKO | F32: WARUNG NOO | G32: WARUNG NOO | H32: Consignment | J32: 10 | K32: =(P2*P32)+(Q2*Q32)+(R2*R32)+(S2*S32)+(T2*T32)+(U2*U32)+(V2*V32)+(W2*W32)+(X2*X32)+(Y2*Y32)+(Z2*Z32)+(AA2*AA32)+(AB2*AB32)+(AC2*AC32)+(AD2*AD32)+(AE2*AE32)+(AF2*AF32)+(AG2*AG32)+(AH2*AH32)+(AI2*AI32)+(AJ2*AJ32)+(AK2*AK32)+(AL2*AL32)+(AM2*AM32)+(AN2*AN32)+(AO2*AO32)+(AP2*AP32)+(AQ2*AQ32)+(AR2*AR32)+(AS2*AS32)+(AT2*AT32)+(AU2*AU32)+(AV2*AV32)+(AW2*AW32)+(AX2*AX32)+(AY2*AY32)+(AZ2*AZ32)+(BA2*BA32)+(BB2*BB32)+(BC2*BC32)+(BD2*BD32)+(BE2*BE32)+(BF2*BF32)+(BG2*BG32)+(BH2*BH32)+(BI2*BI32)+(BJ2*BJ32)+(BK2*BK32)+(BL2*BL32)+(BM2*BM32)+(BN2*BN32)+(BO2*BO32)+(BP2*BP32)+(BQ2*BQ32)+(BR2*BR32)+(BS2*BS32)+(BT2*BT32)+(BU2*BU32)+(BV2*BV32)+(BW2*BW32)+(BX2*BX32)+(BY2*BY32)+(BZ2*BZ32)+(CA2*CA32)+(CB2*CB32)+(CC2*CC32)+(CD2*CD32) | L32: =K32-(K32*J32/100) | M32: =ROUND(L32/1.11, 2) | N32: =SUM(P32:CD32) | O32: =COUNTIF(P32:CD32,">0") | P32: 0 | Q32: 0 | R32: 0 | S32: 0 | T32: 0 | U32: 0 | V32: 0 | W32: 0 | X32: 0 | Y32: 0 | Z32: 0 | AA32: 0 | AB32: 0 | AC32: 0 | AD32: 0 | AE32: 0 | AF32: 0 | AG32: 0 | AH32: 0 | AI32: 0 | AJ32: 0 | AK32: 0 | AL32: 0 | AM32: 0 | AN32: 0 | AO32: 0 | AP32: 0 | AQ32: 0 | AR32: 0 | AS32: 0 | AT32: 0 | AU32: 0 | AV32: 0 | AW32: 0 | AX32: 0 | AY32: 0 | AZ32: 0 | BA32: 0 | BB32: 0 | BC32: 0 | BD32: 0 | BE32: 0 | BF32: 0 | BG32: 0 | BH32: 0 | BI32: 0 | BJ32: 0 | BK32: 0 | BL32: 0 | BM32: 0 | BN32: 0 | BO32: 0 | BP32: 0 | BQ32: 0 | BR32: 0 | BS32: 0 | BT32: 0 | BU32: 0 | BV32: 0 | BW32: 0 | BX32: 0 | BY32: 0 | BZ32: 0 | CA32: 0 | CB32: 0 | CC32: 0 | CD32: 0
A33: 31 | B33: 2026-07-04 | C33: 71306762 | D33: SMTR_02 | E33: (1881580355)WARUNG SULE | F33: WARUNG NOO | G33: WARUNG NOO | H33: Consignment | J33: 10 | K33: =(P2*P33)+(Q2*Q33)+(R2*R33)+(S2*S33)+(T2*T33)+(U2*U33)+(V2*V33)+(W2*W33)+(X2*X33)+(Y2*Y33)+(Z2*Z33)+(AA2*AA33)+(AB2*AB33)+(AC2*AC33)+(AD2*AD33)+(AE2*AE33)+(AF2*AF33)+(AG2*AG33)+(AH2*AH33)+(AI2*AI33)+(AJ2*AJ33)+(AK2*AK33)+(AL2*AL33)+(AM2*AM33)+(AN2*AN33)+(AO2*AO33)+(AP2*AP33)+(AQ2*AQ33)+(AR2*AR33)+(AS2*AS33)+(AT2*AT33)+(AU2*AU33)+(AV2*AV33)+(AW2*AW33)+(AX2*AX33)+(AY2*AY33)+(AZ2*AZ33)+(BA2*BA33)+(BB2*BB33)+(BC2*BC33)+(BD2*BD33)+(BE2*BE33)+(BF2*BF33)+(BG2*BG33)+(BH2*BH33)+(BI2*BI33)+(BJ2*BJ33)+(BK2*BK33)+(BL2*BL33)+(BM2*BM33)+(BN2*BN33)+(BO2*BO33)+(BP2*BP33)+(BQ2*BQ33)+(BR2*BR33)+(BS2*BS33)+(BT2*BT33)+(BU2*BU33)+(BV2*BV33)+(BW2*BW33)+(BX2*BX33)+(BY2*BY33)+(BZ2*BZ33)+(CA2*CA33)+(CB2*CB33)+(CC2*CC33)+(CD2*CD33) | L33: =K33-(K33*J33/100) | M33: =ROUND(L33/1.11, 2) | N33: =SUM(P33:CD33) | O33: =COUNTIF(P33:CD33,">0") | P33: 0 | Q33: 0 | R33: 0 | S33: 0 | T33: 0 | U33: 0 | V33: 0 | W33: 0 | X33: 0 | Y33: 0 | Z33: 0 | AA33: 0 | AB33: 0 | AC33: 0 | AD33: 0 | AE33: 0 | AF33: 0 | AG33: 0 | AH33: 0 | AI33: 0 | AJ33: 0 | AK33: 0 | AL33: 0 | AM33: 0 | AN33: 0 | AO33: 0 | AP33: 0 | AQ33: 0 | AR33: 0 | AS33: 0 | AT33: 0 | AU33: 0 | AV33: 0 | AW33: 0 | AX33: 0 | AY33: 0 | AZ33: 0 | BA33: 0 | BB33: 0 | BC33: 0 | BD33: 0 | BE33: 0 | BF33: 0 | BG33: 0 | BH33: 0 | BI33: 0 | BJ33: 0 | BK33: 0 | BL33: 0 | BM33: 0 | BN33: 0 | BO33: 0 | BP33: 0 | BQ33: 0 | BR33: 0 | BS33: 0 | BT33: 0 | BU33: 0 | BV33: 0 | BW33: 0 | BX33: 0 | BY33: 0 | BZ33: 0 | CA33: 0 | CB33: 0 | CC33: 0 | CD33: 0
A34: 32 | B34: 2026-07-04 | C34: 71306762 | D34: SMTR_02 | E34: (1881583376)TOKO IBU INI | F34: MTI NOO | G34: MTI NOO | H34: Consignment | J34: 10 | K34: =(P2*P34)+(Q2*Q34)+(R2*R34)+(S2*S34)+(T2*T34)+(U2*U34)+(V2*V34)+(W2*W34)+(X2*X34)+(Y2*Y34)+(Z2*Z34)+(AA2*AA34)+(AB2*AB34)+(AC2*AC34)+(AD2*AD34)+(AE2*AE34)+(AF2*AF34)+(AG2*AG34)+(AH2*AH34)+(AI2*AI34)+(AJ2*AJ34)+(AK2*AK34)+(AL2*AL34)+(AM2*AM34)+(AN2*AN34)+(AO2*AO34)+(AP2*AP34)+(AQ2*AQ34)+(AR2*AR34)+(AS2*AS34)+(AT2*AT34)+(AU2*AU34)+(AV2*AV34)+(AW2*AW34)+(AX2*AX34)+(AY2*AY34)+(AZ2*AZ34)+(BA2*BA34)+(BB2*BB34)+(BC2*BC34)+(BD2*BD34)+(BE2*BE34)+(BF2*BF34)+(BG2*BG34)+(BH2*BH34)+(BI2*BI34)+(BJ2*BJ34)+(BK2*BK34)+(BL2*BL34)+(BM2*BM34)+(BN2*BN34)+(BO2*BO34)+(BP2*BP34)+(BQ2*BQ34)+(BR2*BR34)+(BS2*BS34)+(BT2*BT34)+(BU2*BU34)+(BV2*BV34)+(BW2*BW34)+(BX2*BX34)+(BY2*BY34)+(BZ2*BZ34)+(CA2*CA34)+(CB2*CB34)+(CC2*CC34)+(CD2*CD34) | L34: =K34-(K34*J34/100) | M34: =ROUND(L34/1.11, 2) | N34: =SUM(P34:CD34) | O34: =COUNTIF(P34:CD34,">0") | P34: 0 | Q34: 0 | R34: 0 | S34: 0 | T34: 0 | U34: 0 | V34: 0 | W34: 0 | X34: 0 | Y34: 0 | Z34: 0 | AA34: 0 | AB34: 0 | AC34: 0 | AD34: 0 | AE34: 0 | AF34: 0 | AG34: 0 | AH34: 0 | AI34: 0 | AJ34: 0 | AK34: 0 | AL34: 0 | AM34: 0 | AN34: 0 | AO34: 0 | AP34: 0 | AQ34: 0 | AR34: 0 | AS34: 0 | AT34: 0 | AU34: 0 | AV34: 0 | AW34: 0 | AX34: 0 | AY34: 0 | AZ34: 0 | BA34: 0 | BB34: 0 | BC34: 0 | BD34: 0 | BE34: 0 | BF34: 0 | BG34: 0 | BH34: 0 | BI34: 0 | BJ34: 0 | BK34: 0 | BL34: 0 | BM34: 0 | BN34: 0 | BO34: 0 | BP34: 0 | BQ34: 0 | BR34: 0 | BS34: 0 | BT34: 0 | BU34: 0 | BV34: 0 | BW34: 0 | BX34: 0 | BY34: 0 | BZ34: 0 | CA34: 0 | CB34: 0 | CC34: 0 | CD34: 0
A35: 33 | B35: 2026-07-04 | C35: 71306762 | D35: SMTR_02 | E35: (1881586941)SRC SUKOCO 99 TOKO | F35: WARUNG NOO | G35: WARUNG NOO | H35: Consignment | J35: 10 | K35: =(P2*P35)+(Q2*Q35)+(R2*R35)+(S2*S35)+(T2*T35)+(U2*U35)+(V2*V35)+(W2*W35)+(X2*X35)+(Y2*Y35)+(Z2*Z35)+(AA2*AA35)+(AB2*AB35)+(AC2*AC35)+(AD2*AD35)+(AE2*AE35)+(AF2*AF35)+(AG2*AG35)+(AH2*AH35)+(AI2*AI35)+(AJ2*AJ35)+(AK2*AK35)+(AL2*AL35)+(AM2*AM35)+(AN2*AN35)+(AO2*AO35)+(AP2*AP35)+(AQ2*AQ35)+(AR2*AR35)+(AS2*AS35)+(AT2*AT35)+(AU2*AU35)+(AV2*AV35)+(AW2*AW35)+(AX2*AX35)+(AY2*AY35)+(AZ2*AZ35)+(BA2*BA35)+(BB2*BB35)+(BC2*BC35)+(BD2*BD35)+(BE2*BE35)+(BF2*BF35)+(BG2*BG35)+(BH2*BH35)+(BI2*BI35)+(BJ2*BJ35)+(BK2*BK35)+(BL2*BL35)+(BM2*BM35)+(BN2*BN35)+(BO2*BO35)+(BP2*BP35)+(BQ2*BQ35)+(BR2*BR35)+(BS2*BS35)+(BT2*BT35)+(BU2*BU35)+(BV2*BV35)+(BW2*BW35)+(BX2*BX35)+(BY2*BY35)+(BZ2*BZ35)+(CA2*CA35)+(CB2*CB35)+(CC2*CC35)+(CD2*CD35) | L35: =K35-(K35*J35/100) | M35: =ROUND(L35/1.11, 2) | N35: =SUM(P35:CD35) | O35: =COUNTIF(P35:CD35,">0") | P35: 0 | Q35: 0 | R35: 0 | S35: 0 | T35: 0 | U35: 0 | V35: 0 | W35: 0 | X35: 0 | Y35: 0 | Z35: 0 | AA35: 0 | AB35: 0 | AC35: 0 | AD35: 0 | AE35: 0 | AF35: 0 | AG35: 0 | AH35: 0 | AI35: 0 | AJ35: 0 | AK35: 0 | AL35: 0 | AM35: 0 | AN35: 0 | AO35: 0 | AP35: 0 | AQ35: 0 | AR35: 0 | AS35: 0 | AT35: 0 | AU35: 0 | AV35: 0 | AW35: 0 | AX35: 0 | AY35: 0 | AZ35: 0 | BA35: 0 | BB35: 0 | BC35: 0 | BD35: 0 | BE35: 0 | BF35: 0 | BG35: 0 | BH35: 0 | BI35: 0 | BJ35: 0 | BK35: 0 | BL35: 0 | BM35: 0 | BN35: 0 | BO35: 0 | BP35: 0 | BQ35: 0 | BR35: 0 | BS35: 0 | BT35: 0 | BU35: 0 | BV35: 0 | BW35: 0 | BX35: 0 | BY35: 0 | BZ35: 0 | CA35: 0 | CB35: 0 | CC35: 0 | CD35: 0
A36: 34 | B36: 2026-07-04 | C36: 71306762 | D36: SMTR_02 | E36: (1881586943)Samudra TOKO | F36: WARUNG NOO | G36: WARUNG NOO | H36: Consignment | J36: 10 | K36: =(P2*P36)+(Q2*Q36)+(R2*R36)+(S2*S36)+(T2*T36)+(U2*U36)+(V2*V36)+(W2*W36)+(X2*X36)+(Y2*Y36)+(Z2*Z36)+(AA2*AA36)+(AB2*AB36)+(AC2*AC36)+(AD2*AD36)+(AE2*AE36)+(AF2*AF36)+(AG2*AG36)+(AH2*AH36)+(AI2*AI36)+(AJ2*AJ36)+(AK2*AK36)+(AL2*AL36)+(AM2*AM36)+(AN2*AN36)+(AO2*AO36)+(AP2*AP36)+(AQ2*AQ36)+(AR2*AR36)+(AS2*AS36)+(AT2*AT36)+(AU2*AU36)+(AV2*AV36)+(AW2*AW36)+(AX2*AX36)+(AY2*AY36)+(AZ2*AZ36)+(BA2*BA36)+(BB2*BB36)+(BC2*BC36)+(BD2*BD36)+(BE2*BE36)+(BF2*BF36)+(BG2*BG36)+(BH2*BH36)+(BI2*BI36)+(BJ2*BJ36)+(BK2*BK36)+(BL2*BL36)+(BM2*BM36)+(BN2*BN36)+(BO2*BO36)+(BP2*BP36)+(BQ2*BQ36)+(BR2*BR36)+(BS2*BS36)+(BT2*BT36)+(BU2*BU36)+(BV2*BV36)+(BW2*BW36)+(BX2*BX36)+(BY2*BY36)+(BZ2*BZ36)+(CA2*CA36)+(CB2*CB36)+(CC2*CC36)+(CD2*CD36) | L36: =K36-(K36*J36/100) | M36: =ROUND(L36/1.11, 2) | N36: =SUM(P36:CD36) | O36: =COUNTIF(P36:CD36,">0") | P36: 0 | Q36: 0 | R36: 0 | S36: 0 | T36: 0 | U36: 0 | V36: 0 | W36: 0 | X36: 0 | Y36: 0 | Z36: 0 | AA36: 0 | AB36: 0 | AC36: 0 | AD36: 0 | AE36: 0 | AF36: 0 | AG36: 0 | AH36: 0 | AI36: 0 | AJ36: 0 | AK36: 0 | AL36: 0 | AM36: 0 | AN36: 0 | AO36: 0 | AP36: 0 | AQ36: 0 | AR36: 0 | AS36: 0 | AT36: 0 | AU36: 0 | AV36: 0 | AW36: 0 | AX36: 0 | AY36: 0 | AZ36: 0 | BA36: 0 | BB36: 0 | BC36: 0 | BD36: 0 | BE36: 0 | BF36: 0 | BG36: 0 | BH36: 0 | BI36: 0 | BJ36: 0 | BK36: 0 | BL36: 0 | BM36: 0 | BN36: 0 | BO36: 0 | BP36: 0 | BQ36: 0 | BR36: 0 | BS36: 0 | BT36: 0 | BU36: 0 | BV36: 0 | BW36: 0 | BX36: 0 | BY36: 0 | BZ36: 0 | CA36: 0 | CB36: 0 | CC36: 0 | CD36: 0
A37: 35 | B37: 2026-07-04 | C37: 71306762 | D37: SMTR_02 | E37: (1881586947)NISA TOKO | F37: WARUNG NOO | G37: WARUNG NOO | H37: Consignment | J37: 10 | K37: =(P2*P37)+(Q2*Q37)+(R2*R37)+(S2*S37)+(T2*T37)+(U2*U37)+(V2*V37)+(W2*W37)+(X2*X37)+(Y2*Y37)+(Z2*Z37)+(AA2*AA37)+(AB2*AB37)+(AC2*AC37)+(AD2*AD37)+(AE2*AE37)+(AF2*AF37)+(AG2*AG37)+(AH2*AH37)+(AI2*AI37)+(AJ2*AJ37)+(AK2*AK37)+(AL2*AL37)+(AM2*AM37)+(AN2*AN37)+(AO2*AO37)+(AP2*AP37)+(AQ2*AQ37)+(AR2*AR37)+(AS2*AS37)+(AT2*AT37)+(AU2*AU37)+(AV2*AV37)+(AW2*AW37)+(AX2*AX37)+(AY2*AY37)+(AZ2*AZ37)+(BA2*BA37)+(BB2*BB37)+(BC2*BC37)+(BD2*BD37)+(BE2*BE37)+(BF2*BF37)+(BG2*BG37)+(BH2*BH37)+(BI2*BI37)+(BJ2*BJ37)+(BK2*BK37)+(BL2*BL37)+(BM2*BM37)+(BN2*BN37)+(BO2*BO37)+(BP2*BP37)+(BQ2*BQ37)+(BR2*BR37)+(BS2*BS37)+(BT2*BT37)+(BU2*BU37)+(BV2*BV37)+(BW2*BW37)+(BX2*BX37)+(BY2*BY37)+(BZ2*BZ37)+(CA2*CA37)+(CB2*CB37)+(CC2*CC37)+(CD2*CD37) | L37: =K37-(K37*J37/100) | M37: =ROUND(L37/1.11, 2) | N37: =SUM(P37:CD37) | O37: =COUNTIF(P37:CD37,">0") | P37: 0 | Q37: 0 | R37: 0 | S37: 0 | T37: 0 | U37: 0 | V37: 0 | W37: 0 | X37: 0 | Y37: 0 | Z37: 0 | AA37: 0 | AB37: 0 | AC37: 0 | AD37: 0 | AE37: 0 | AF37: 0 | AG37: 0 | AH37: 0 | AI37: 0 | AJ37: 0 | AK37: 0 | AL37: 0 | AM37: 0 | AN37: 0 | AO37: 0 | AP37: 0 | AQ37: 0 | AR37: 0 | AS37: 0 | AT37: 0 | AU37: 0 | AV37: 0 | AW37: 0 | AX37: 0 | AY37: 0 | AZ37: 0 | BA37: 0 | BB37: 0 | BC37: 0 | BD37: 0 | BE37: 0 | BF37: 0 | BG37: 0 | BH37: 0 | BI37: 0 | BJ37: 0 | BK37: 0 | BL37: 0 | BM37: 0 | BN37: 0 | BO37: 0 | BP37: 0 | BQ37: 0 | BR37: 0 | BS37: 0 | BT37: 0 | BU37: 0 | BV37: 0 | BW37: 0 | BX37: 0 | BY37: 0 | BZ37: 0 | CA37: 0 | CB37: 0 | CC37: 0 | CD37: 0
A38: 36 | B38: 2026-07-04 | C38: 71306762 | D38: SMTR_02 | E38: (1881587628)FAHRA TOKO | F38: WARUNG NOO | G38: WARUNG NOO | H38: Consignment | J38: 10 | K38: =(P2*P38)+(Q2*Q38)+(R2*R38)+(S2*S38)+(T2*T38)+(U2*U38)+(V2*V38)+(W2*W38)+(X2*X38)+(Y2*Y38)+(Z2*Z38)+(AA2*AA38)+(AB2*AB38)+(AC2*AC38)+(AD2*AD38)+(AE2*AE38)+(AF2*AF38)+(AG2*AG38)+(AH2*AH38)+(AI2*AI38)+(AJ2*AJ38)+(AK2*AK38)+(AL2*AL38)+(AM2*AM38)+(AN2*AN38)+(AO2*AO38)+(AP2*AP38)+(AQ2*AQ38)+(AR2*AR38)+(AS2*AS38)+(AT2*AT38)+(AU2*AU38)+(AV2*AV38)+(AW2*AW38)+(AX2*AX38)+(AY2*AY38)+(AZ2*AZ38)+(BA2*BA38)+(BB2*BB38)+(BC2*BC38)+(BD2*BD38)+(BE2*BE38)+(BF2*BF38)+(BG2*BG38)+(BH2*BH38)+(BI2*BI38)+(BJ2*BJ38)+(BK2*BK38)+(BL2*BL38)+(BM2*BM38)+(BN2*BN38)+(BO2*BO38)+(BP2*BP38)+(BQ2*BQ38)+(BR2*BR38)+(BS2*BS38)+(BT2*BT38)+(BU2*BU38)+(BV2*BV38)+(BW2*BW38)+(BX2*BX38)+(BY2*BY38)+(BZ2*BZ38)+(CA2*CA38)+(CB2*CB38)+(CC2*CC38)+(CD2*CD38) | L38: =K38-(K38*J38/100) | M38: =ROUND(L38/1.11, 2) | N38: =SUM(P38:CD38) | O38: =COUNTIF(P38:CD38,">0") | P38: 0 | Q38: 0 | R38: 0 | S38: 0 | T38: 0 | U38: 0 | V38: 0 | W38: 0 | X38: 0 | Y38: 0 | Z38: 0 | AA38: 0 | AB38: 0 | AC38: 0 | AD38: 0 | AE38: 0 | AF38: 0 | AG38: 0 | AH38: 0 | AI38: 0 | AJ38: 0 | AK38: 0 | AL38: 0 | AM38: 0 | AN38: 0 | AO38: 0 | AP38: 0 | AQ38: 0 | AR38: 0 | AS38: 0 | AT38: 0 | AU38: 0 | AV38: 0 | AW38: 0 | AX38: 0 | AY38: 0 | AZ38: 0 | BA38: 0 | BB38: 0 | BC38: 0 | BD38: 0 | BE38: 0 | BF38: 0 | BG38: 0 | BH38: 0 | BI38: 0 | BJ38: 0 | BK38: 0 | BL38: 0 | BM38: 0 | BN38: 0 | BO38: 0 | BP38: 0 | BQ38: 0 | BR38: 0 | BS38: 0 | BT38: 0 | BU38: 0 | BV38: 0 | BW38: 0 | BX38: 0 | BY38: 0 | BZ38: 0 | CA38: 0 | CB38: 0 | CC38: 0 | CD38: 0
